Workbook
Name 攻击: 角色卡!$U$6:$U$9
Name 组合风格_25消耗: 时髦动作!$F$28:$F$32
Name 策定山河_5消耗: 时髦动作!$D$5
Name 组合风格_20消耗: 时髦动作!$F$22:$F$26
Name 组合风格_5消耗: 时髦动作!$F$4:$F$8
Name 组合风格_15消耗: 时髦动作!$F$16:$F$20
Name 组合风格_10消耗: 时髦动作!$F$10:$F$14
Name 策定山河_10消耗: 时髦动作!$D$6
Name 策定山河_15消耗: 时髦动作!$D$7
Name 策定山河_20消耗: 时髦动作!$D$8
Name 策定山河_25消耗: 时髦动作!$D$9
Name 玩世不恭_5消耗: 时髦动作!$D$15
Name 玩世不恭_10消耗: 时髦动作!$D$16
Name 玩世不恭_15消耗: 时髦动作!$D$17
Name 玩世不恭_20消耗: 时髦动作!$D$18
Name 玩世不恭_25消耗: 时髦动作!$D$19
Name 快意恩仇_5消耗: 时髦动作!$D$20
Name 快意恩仇_10消耗: 时髦动作!$D$21
Name 快意恩仇_15消耗: 时髦动作!$D$22
Name 快意恩仇_20消耗: 时髦动作!$D$23
Name 快意恩仇_25消耗: 时髦动作!$D$24
Name 百折不挠_5消耗: 时髦动作!$D$25
Name 百折不挠_10消耗: 时髦动作!$D$26
Name 百折不挠_15消耗: 时髦动作!$D$27
Name 百折不挠_20消耗: 时髦动作!$D$28
Name 百折不挠_25消耗: 时髦动作!$D$29
Name 其他风格_5消耗: 时髦动作!$D$33
Name 其他风格_10消耗: 时髦动作!$D$34
Name 其他风格_15消耗: 时髦动作!$D$35
Name 其他风格_20消耗: 时髦动作!$D$36
Name 其他风格_25消耗: 时髦动作!$D$37
Name _专长描述1: 专长!$E$2
Name _专长描述2: 专长!$F$2
Name _专长名称1: 专长!$I$4:$I$33
Name _专长名称2: 专长!$J$4:$J$33
Name _专精名称2: 通用效果!$K$4:$K$19
Name _专精名称1: 通用效果!$J$4:$J$19
Name _灵能印记1: 灵能印记!$I$4:$I$30
Name _灵能印记2: 灵能印记!$J$4:$J$30
Name 武技: 武技!$B$4:$B$60
Name 武技_效果1: 武技!$J$4
Name 武技_效果2: 武技!$J$5
Name 武技_效果3: 武技!$J$6
Name 武技_效果4: 武技!$J$7
Name 武技_效果5: 武技!$J$8
Name 武技_效果6: 武技!$J$9
Name 武技_效果7: 武技!$J$10
Name 武技_效果8: 武技!$J$11
Name 武技_效果9: 武技!$J$12
Name 武技_效果10: 武技!$J$13
Name 武技_效果11: 武技!$J$14
Name 武技_效果12: 武技!$J$15
Name 武技_效果13: 武技!$J$16
Name 武技_效果14: 武技!$J$17
Name 武技_效果15: 武技!$J$18
Name 武技_效果16: 武技!$J$19
Name 武技_效果17: 武技!$J$20
Name 武技_效果18: 武技!$J$21
Name 术法: 术法!$B$4:$B$133
Name 术法_效果1: 术法!$K$6

Sheet 角色卡
B1: 本卡用以进行《狩魂者TRPG》游戏，使用规则为正式版，如与规则书有出入请以规则书为准。建议使用电脑WPS打开。
B2: 狩魂者官方QQ交流一群579621236、二群1027976807。更新日志见附表。如发现BUG或有功能建议，请联系QQ2665468556——by肠子里的黄
B4: 你的头像 （插入图片时需手动撤销工作表保护） | Q4: 灵能力 | AY4: 时髦动作 | CI4: ☑
Q5: 灵能力名称 | AE5: 灵能力专精 | AJ5: =IF(V21>=2,CI4,CI5) -> ☐ | AQ5: =IF(V21>=9,CI4,CI5) -> ☐ | AY5: 时髦风格 | BC5: 消耗 | BG5: 动作名和效果 | CI5: ☐
AY6: 通用 | BC6: 50时髦值 | BG6: 超灵觉醒-你进行攻击检定时，你通过加骰获得的骰值全部翻倍，然后你投掷一枚 D6，获得对应数值的经验值。
Q7: 灵能力描述 | CI7: =IF(ISBLANK(V17),"",INT(5+V17/2))
BC8: 5时髦值 | CI8: =IF(AND(V19<>"",V21<>""),5+2*V19+V21,"")
BC10: 10时髦值
BC12: 15时髦值
Q14: =IF(V21>=7,"全文不得多于100字，可拥有至多四个灵能力标签。","全文不得多于80字，可拥有至多三个灵能力标签。") -> 全文不得多于80字，可拥有至多三个灵能力标签。 | BC14: 20时髦值
B16: 狩魂者信息 | Q16: 基础属性 | AH16: 技能表 | BC16: 25时髦值
B17: 姓名 | J17: 代号 | Q17: 体魄 | T17: =IF(V17=1,"E",IF(V17=2,"D",IF(V17=3,"C",IF(V17=4,"B",IF(V17=5,"A",IF(V17=6,"S",IF(V17=7,"SS",IF(V17=8,"SSS",IF(V17=9,"SSS+",IF(V17="","",IF(V17>9,"?","?"))))))))))) | X17: 武技强度 | AC17: =IF(ISBLANK(V17),"",INT(V17/2)) | AH17: 技能名称 | AL17: 属性附加 | AP17: 自由分配 | AT17: 技能等级
B18: 性别 | J18: 年龄 | AH18: 运动 | AL18: =IF(ISBLANK(V17),"",INT(V17/2)) | AT18: =IF(OR(AL18<>"",AP18<>""),SUM(AL18,AP18),"")
B19: 狩魂羁绊 | Q19: 智慧 | T19: =IF(V19=1,"E",IF(V19=2,"D",IF(V19=3,"C",IF(V19=4,"B",IF(V19=5,"A",IF(V19=6,"S",IF(V19=7,"SS",IF(V19=8,"SSS",IF(V19=9,"SSS+",IF(V19="","",IF(V19>9,"?","?"))))))))))) | X19: 术法强度 | AC19: =IF(ISBLANK(V19),"",INT(V19/2)) | AH19: 操作 | AL19: =IF(ISBLANK(V19),"",INT(V19/2)) | AT19: =IF(OR(AL19<>"",AP19<>""),SUM(AL19,AP19),"") | AY19: =IF(OR(V21>=3,T26>=12),CI4,CI5) -> ☐ | AZ19: 灵魂武器 | BJ19: =IF(T26>=14,CI4,CI5) -> ☐ | BK19: 一挡绝技 | BV19: =IF(T26>=18,CI4,CI5) -> ☐ | BW19: 二挡绝技
AH20: 隐秘 | AL20: =IF(ISBLANK(V19),"",INT(V19/2)) | AT20: =IF(OR(AL20<>"",AP20<>""),SUM(AL20,AP20),"") | AY20: 名称 | BJ20: 名称 | BV20: 名称
Q21: 心魂 | T21: =IF(V21=1,"E",IF(V21=2,"D",IF(V21=3,"C",IF(V21=4,"B",IF(V21=5,"A",IF(V21=6,"S",IF(V21=7,"SS",IF(V21=8,"SSS",IF(V21=9,"SSS+",IF(V21="","",IF(V21>9,"?","?"))))))))))) | X21: 灵能力强度 | AC21: =IF(ISBLANK(V21),"",INT(V21/2)) | AH21: 调查 | AL21: =IF(ISBLANK(V19),"",INT(V19/2)) | AT21: =IF(OR(AL21<>"",AP21<>""),SUM(AL21,AP21),"")
AH22: 洞察 | AL22: =IF(ISBLANK(V21),"",INT(V21/2)) | AT22: =IF(OR(AL22<>"",AP22<>""),SUM(AL22,AP22),"") | AY22: 灵能印记 | BC22: =IF(OR(角色卡!V21>=3,角色卡!T26>=12),CI4,CI5) -> ☐ | BG22: ☐ | BJ22: 类型 | BV22: 类型
AH23: 说服 | AL23: =IF(ISBLANK(V21),"",INT(V21/2)) | AT23: =IF(OR(AL23<>"",AP23<>""),SUM(AL23,AP23),"") | BC23: 1 | BG23: 3
B24: 业力标签 | Q24: 生命值 | T24: =IF(W24="","",W24) | V24: / | W24: =IF(OR(TRIM(E35)="深度灵体合一",TRIM(AU35)="深度灵体合一"),1,CI7) | Y24: 灵力值 | AB24: =IF(AE24="","",AE24) | AD24: / | AE24: =IF(OR(TRIM(E35)="深度灵体合一",TRIM(AU35)="深度灵体合一"),CI8+(CI7-1)*4-5,CI8) | AH24: 狩魂学识 | AT24: =IF(OR(AL24<>"",AP24<>""),SUM(AL24,AP24),IF(V19="","","0")) | BC24: =IF(V21>=5,CI4,CI5) -> ☐ | BG24: ☐ | BJ24: 对应魂魄 | BN24: =IF(BN22=0,"",VLOOKUP(BN22,绝技!$B$4:$C$11,2,0)) | BV24: 对应魂魄 | BZ24: =IF(BZ22=0,"",VLOOKUP(BZ22,绝技!$B$12:$C$15,2,0))
B25: 背景故事 | AH25: 总技能点 | AM25: =IF(ISBLANK(V19),"",IF(V19=1,"0",IF(V19=2,"1",IF(V19=3,"2",IF(V19=4,"3",IF(V19=5,"4",IF(V19=6,"5",IF(V19=7,"6",IF(V19=8,"7",IF(V19=9,"8")))))))))) | AP25: 剩余技能点 | AU25: =IF(ISBLANK(V19),"",AM25-SUM(AP18:AP24)) | BC25: 2 | BG25: 4
Q26: 灵识 | V26: 初始 时髦值 | Y26: =IF(OR(TRIM(E35)="人名树影",TRIM(AU35)="人名树影"),20,10) -> 10 | AB26: 道具点 上限 | AE26: =IF(OR(TRIM(E35)="有备而来",TRIM(AU35)="有备而来"),4,3) -> 3 | AG26: 经验值 | AJ26: 0 | AL26: =IF(ISBLANK(T26),"←请填写灵识等级",IF(OR(V17<1,V19<1,V21<1),"单项属性不得低于1",IF(AND(T26=9,OR(V17>5,V19>5,V21>5)),"9灵识开卡，单项属性不可超过5",IF(T26=V17+V19+V21,"",IF(T26>V17+V19+V21,"三维属性之和未达灵识等级","三维属性之和超出灵识等级"))))) -> ←请填写灵识等级 | AS26: 事件业力 | AV26: 0 | AY26: 外形描述 | BJ26: 效果 | BV26: 效果
Q29: 经历标签 | AH29: 备注
BJ30: 绝技描述 | BV30: 绝技描述
B34: =IF(T26>=10,CI4,CI5) -> ☐ | C34: 专长1 | AR34: =IF(T26>=16,CI4,CI5) -> ☐ | AS34: 专长2
B35: 名称 | J35: 描述 | AR35: 名称 | AZ35: 描述
B37: 武技表 | AR37: 术法表
B38: 名称 | H38: 消耗 | M38: 目标 | P38: 辅助 | R38: 秘传 | T38: 效果 | AH38: 风味描述 | AR38: 名称 | AX38: 消耗 | BC38: 目标 | BF38: 类别 | BH38: 秘传 | BJ38: 类型 | BM38: 效果 | BX38: 风味描述
H39: =VLOOKUP(B39,武技!$B$4:$H$60,2,0) | M39: =VLOOKUP(B39,武技!$B$4:$H$60,3,0) | P39: =VLOOKUP(B39,武技!$B$4:$H$60,4,0) | R39: =VLOOKUP(B39,武技!$B$4:$H$60,5,0) | AH39: =VLOOKUP(B39,武技!$B$4:$H$60,7,0) | AX39: =VLOOKUP(AR39,术法!$B$4:$I$133,2,0) | BC39: =VLOOKUP(AR39,术法!$B$4:$I$133,3,0) | BF39: =VLOOKUP(AR39,术法!$B$4:$I$133,4,0) | BH39: =VLOOKUP(AR39,术法!$B$4:$I$133,5,0) | BJ39: =VLOOKUP(AR39,术法!$B$4:$I$133,6,0) | BX39: =VLOOKUP(AR39,术法!$B$4:$I$133,8,0)
H41: =VLOOKUP(B41,武技!$B$4:$H$60,2,0) | M41: =VLOOKUP(B41,武技!$B$4:$H$60,3,0) | P41: =VLOOKUP(B41,武技!$B$4:$H$60,4,0) | R41: =VLOOKUP(B41,武技!$B$4:$H$60,5,0) | AH41: =VLOOKUP(B41,武技!$B$4:$H$60,7,0) | AX41: =VLOOKUP(AR41,术法!$B$4:$I$133,2,0) | BC41: =VLOOKUP(AR41,术法!$B$4:$I$133,3,0) | BF41: =VLOOKUP(AR41,术法!$B$4:$I$133,4,0) | BH41: =VLOOKUP(AR41,术法!$B$4:$I$133,5,0) | BJ41: =VLOOKUP(AR41,术法!$B$4:$I$133,6,0) | BX41: =VLOOKUP(AR41,术法!$B$4:$I$133,8,0)
H43: =VLOOKUP(B43,武技!$B$4:$H$60,2,0) | M43: =VLOOKUP(B43,武技!$B$4:$H$60,3,0) | P43: =VLOOKUP(B43,武技!$B$4:$H$60,4,0) | R43: =VLOOKUP(B43,武技!$B$4:$H$60,5,0) | AH43: =VLOOKUP(B43,武技!$B$4:$H$60,7,0) | AX43: =VLOOKUP(AR43,术法!$B$4:$I$133,2,0) | BC43: =VLOOKUP(AR43,术法!$B$4:$I$133,3,0) | BF43: =VLOOKUP(AR43,术法!$B$4:$I$133,4,0) | BH43: =VLOOKUP(AR43,术法!$B$4:$I$133,5,0) | BJ43: =VLOOKUP(AR43,术法!$B$4:$I$133,6,0) | BX43: =VLOOKUP(AR43,术法!$B$4:$I$133,8,0)
H45: =VLOOKUP(B45,武技!$B$4:$H$60,2,0) | M45: =VLOOKUP(B45,武技!$B$4:$H$60,3,0) | P45: =VLOOKUP(B45,武技!$B$4:$H$60,4,0) | R45: =VLOOKUP(B45,武技!$B$4:$H$60,5,0) | AH45: =VLOOKUP(B45,武技!$B$4:$H$60,7,0) | AX45: =VLOOKUP(AR45,术法!$B$4:$I$133,2,0) | BC45: =VLOOKUP(AR45,术法!$B$4:$I$133,3,0) | BF45: =VLOOKUP(AR45,术法!$B$4:$I$133,4,0) | BH45: =VLOOKUP(AR45,术法!$B$4:$I$133,5,0) | BJ45: =VLOOKUP(AR45,术法!$B$4:$I$133,6,0) | BX45: =VLOOKUP(AR45,术法!$B$4:$I$133,8,0)
H47: =VLOOKUP(B47,武技!$B$4:$H$60,2,0) | M47: =VLOOKUP(B47,武技!$B$4:$H$60,3,0) | P47: =VLOOKUP(B47,武技!$B$4:$H$60,4,0) | R47: =VLOOKUP(B47,武技!$B$4:$H$60,5,0) | AH47: =VLOOKUP(B47,武技!$B$4:$H$60,7,0) | AX47: =VLOOKUP(AR47,术法!$B$4:$I$133,2,0) | BC47: =VLOOKUP(AR47,术法!$B$4:$I$133,3,0) | BF47: =VLOOKUP(AR47,术法!$B$4:$I$133,4,0) | BH47: =VLOOKUP(AR47,术法!$B$4:$I$133,5,0) | BJ47: =VLOOKUP(AR47,术法!$B$4:$I$133,6,0) | BX47: =VLOOKUP(AR47,术法!$B$4:$I$133,8,0)
H49: =VLOOKUP(B49,武技!$B$4:$H$60,2,0) | M49: =VLOOKUP(B49,武技!$B$4:$H$60,3,0) | P49: =VLOOKUP(B49,武技!$B$4:$H$60,4,0) | R49: =VLOOKUP(B49,武技!$B$4:$H$60,5,0) | AH49: =VLOOKUP(B49,武技!$B$4:$H$60,7,0) | AX49: =VLOOKUP(AR49,术法!$B$4:$I$133,2,0) | BC49: =VLOOKUP(AR49,术法!$B$4:$I$133,3,0) | BF49: =VLOOKUP(AR49,术法!$B$4:$I$133,4,0) | BH49: =VLOOKUP(AR49,术法!$B$4:$I$133,5,0) | BJ49: =VLOOKUP(AR49,术法!$B$4:$I$133,6,0) | BX49: =VLOOKUP(AR49,术法!$B$4:$I$133,8,0)
H51: =VLOOKUP(B51,武技!$B$4:$H$60,2,0) | M51: =VLOOKUP(B51,武技!$B$4:$H$60,3,0) | P51: =VLOOKUP(B51,武技!$B$4:$H$60,4,0) | R51: =VLOOKUP(B51,武技!$B$4:$H$60,5,0) | AH51: =VLOOKUP(B51,武技!$B$4:$H$60,7,0) | AX51: =VLOOKUP(AR51,术法!$B$4:$I$133,2,0) | BC51: =VLOOKUP(AR51,术法!$B$4:$I$133,3,0) | BF51: =VLOOKUP(AR51,术法!$B$4:$I$133,4,0) | BH51: =VLOOKUP(AR51,术法!$B$4:$I$133,5,0) | BJ51: =VLOOKUP(AR51,术法!$B$4:$I$133,6,0) | BX51: =VLOOKUP(AR51,术法!$B$4:$I$133,8,0)
H53: =VLOOKUP(B53,武技!$B$4:$H$60,2,0) | M53: =VLOOKUP(B53,武技!$B$4:$H$60,3,0) | P53: =VLOOKUP(B53,武技!$B$4:$H$60,4,0) | R53: =VLOOKUP(B53,武技!$B$4:$H$60,5,0) | AH53: =VLOOKUP(B53,武技!$B$4:$H$60,7,0) | AX53: =VLOOKUP(AR53,术法!$B$4:$I$133,2,0) | BC53: =VLOOKUP(AR53,术法!$B$4:$I$133,3,0) | BF53: =VLOOKUP(AR53,术法!$B$4:$I$133,4,0) | BH53: =VLOOKUP(AR53,术法!$B$4:$I$133,5,0) | BJ53: =VLOOKUP(AR53,术法!$B$4:$I$133,6,0) | BX53: =VLOOKUP(AR53,术法!$B$4:$I$133,8,0)
H55: =VLOOKUP(B55,武技!$B$4:$H$60,2,0) | M55: =VLOOKUP(B55,武技!$B$4:$H$60,3,0) | P55: =VLOOKUP(B55,武技!$B$4:$H$60,4,0) | R55: =VLOOKUP(B55,武技!$B$4:$H$60,5,0) | AH55: =VLOOKUP(B55,武技!$B$4:$H$60,7,0) | AX55: =VLOOKUP(AR55,术法!$B$4:$I$133,2,0) | BC55: =VLOOKUP(AR55,术法!$B$4:$I$133,3,0) | BF55: =VLOOKUP(AR55,术法!$B$4:$I$133,4,0) | BH55: =VLOOKUP(AR55,术法!$B$4:$I$133,5,0) | BJ55: =VLOOKUP(AR55,术法!$B$4:$I$133,6,0) | BX55: =VLOOKUP(AR55,术法!$B$4:$I$133,8,0)
H57: =VLOOKUP(B57,武技!$B$4:$H$60,2,0) | M57: =VLOOKUP(B57,武技!$B$4:$H$60,3,0) | P57: =VLOOKUP(B57,武技!$B$4:$H$60,4,0) | R57: =VLOOKUP(B57,武技!$B$4:$H$60,5,0) | AH57: =VLOOKUP(B57,武技!$B$4:$H$60,7,0) | AX57: =VLOOKUP(AR57,术法!$B$4:$I$133,2,0) | BC57: =VLOOKUP(AR57,术法!$B$4:$I$133,3,0) | BF57: =VLOOKUP(AR57,术法!$B$4:$I$133,4,0) | BH57: =VLOOKUP(AR57,术法!$B$4:$I$133,5,0) | BJ57: =VLOOKUP(AR57,术法!$B$4:$I$133,6,0) | BX57: =VLOOKUP(AR57,术法!$B$4:$I$133,8,0)
H59: =VLOOKUP(B59,武技!$B$4:$H$60,2,0) | M59: =VLOOKUP(B59,武技!$B$4:$H$60,3,0) | P59: =VLOOKUP(B59,武技!$B$4:$H$60,4,0) | R59: =VLOOKUP(B59,武技!$B$4:$H$60,5,0) | AH59: =VLOOKUP(B59,武技!$B$4:$H$60,7,0) | AX59: =VLOOKUP(AR59,术法!$B$4:$I$133,2,0) | BC59: =VLOOKUP(AR59,术法!$B$4:$I$133,3,0) | BF59: =VLOOKUP(AR59,术法!$B$4:$I$133,4,0) | BH59: =VLOOKUP(AR59,术法!$B$4:$I$133,5,0) | BJ59: =VLOOKUP(AR59,术法!$B$4:$I$133,6,0) | BX59: =VLOOKUP(AR59,术法!$B$4:$I$133,8,0)
H61: =VLOOKUP(B61,武技!$B$4:$H$60,2,0) | M61: =VLOOKUP(B61,武技!$B$4:$H$60,3,0) | P61: =VLOOKUP(B61,武技!$B$4:$H$60,4,0) | R61: =VLOOKUP(B61,武技!$B$4:$H$60,5,0) | AH61: =VLOOKUP(B61,武技!$B$4:$H$60,7,0) | AX61: =VLOOKUP(AR61,术法!$B$4:$I$133,2,0) | BC61: =VLOOKUP(AR61,术法!$B$4:$I$133,3,0) | BF61: =VLOOKUP(AR61,术法!$B$4:$I$133,4,0) | BH61: =VLOOKUP(AR61,术法!$B$4:$I$133,5,0) | BJ61: =VLOOKUP(AR61,术法!$B$4:$I$133,6,0) | BX61: =VLOOKUP(AR61,术法!$B$4:$I$133,8,0)
... H73: =VLOOKUP(B73,武技!$B$4:$H$60,2,0) | M73: =VLOOKUP(B73,武技!$B$4:$H$60,3,0) | P73: =VLOOKUP(B73,武技!$B$4:$H$60,4,0) | R73: =VLOOKUP(B73,武技!$B$4:$H$60,5,0) | AH73: =VLOOKUP(B73,武技!$B$4:$H$60,7,0) | AX73: =VLOOKUP(AR73,术法!$B$4:$I$133,2,0) | BC73: =VLOOKUP(AR73,术法!$B$4:$I$133,3,0) | BF73: =VLOOKUP(AR73,术法!$B$4:$I$133,4,0) | BH73: =VLOOKUP(AR73,术法!$B$4:$I$133,5,0) | BJ73: =VLOOKUP(AR73,术法!$B$4:$I$133,6,0) | BX73: =VLOOKUP(AR73,术法!$B$4:$I$133,8,0)
...

Sheet 属性与灵识
B2: 属性等级表 | AB2: 灵识提升表
B4: 等级 | D4: 属性值 | F4: 属性强度 | I4: 体魄 | O4: 智慧 | U4: 心魂 | AB4: 灵识 | AD4: 狩魂者获得成长
B6: E | D6: 1 | F6: 0 | I6: 习得基础武技“常规攻击”和基础术法“灵迹”，从基础术法“凝爆”和 “超感”中选择一个习得，然后在智慧等级5习得另外一个。 | AB6: 10 | AD6: 获得一项自选专长
AB7: 12 | AD7: 获得你的灵魂武器
B8: D | D8: 2 | F8: 1 | I8: 可以学习普通武技 习得1项自选武技 | O8: 可以学习普通术法 习得2项自选术法 获得1点技能点 | U8: 获得1项灵能力专精 | AB8: 14 | AD8: 习得一挡狩魂绝技
AB9: 16 | AD9: 获得另一项新的自选专长
AB10: 18 | AD10: 习得二挡狩魂绝技
B11: C | D11: 3 | F11: 1 | I11: 习得1项自选武技 | O11: 习得2项自选术法 获得1点技能点 | U11: 提前获得灵魂武器
AB12: 你目前的灵识等级为 | AM12: =IF(角色卡!T26="","",角色卡!T26) | AN12: 级，因此你累计可以获得以下提升：
B13: B | D13: 4 | F13: 2 | I13: - | O13: 获得1点技能点 | U13: - | AB13: =IF(AM12<=3,"","习得基础武技“常规攻击”和基础术法“灵迹”，从基础术法“凝爆”和“超感”中选择一个习得") -> 习得基础武技“常规攻击”和基础术法“灵迹”，从基础术法“凝爆”和“超感”中选择一个习得
B14: A | D14: 5 | F14: 2 | I14: 习得1项自选武技 | O14: 习得2项自选术法 获得1点技能点 | U14: 觉醒额外灵能印记 | AB14: =IF(角色卡!V19>=5,"习得基础术法“凝爆”和“超感”中的另一个","")
AB15: =IF(角色卡!V17>=2,"可以学习普通武技","不可学习普通武技") -> 不可学习普通武技 | AO15: =IF(角色卡!V19>=2,"可以学习普通术法","不可学习普通术法") -> 不可学习普通术法
B16: S | D16: 6 | F16: 3 | I16: - | O16: 获得1点技能点 | U16: - | AB16: =IF(角色卡!V17>=7,"可以学习秘传武技","不可学习秘传武技") -> 不可学习秘传武技 | AO16: =IF(角色卡!V19>=7,"可以学习秘传术法","不可学习秘传术法") -> 不可学习秘传术法
B17: SS | D17: 7 | F17: 3 | I17: 可以学习秘传武技 习得1项自选武技 | O17: 可以学习秘传术法 习得2项自选术法 获得1点技能点 | U17: 创造新的灵能力标签 | AB17: 基于体魄等级，可习得共计 | AI17: =IF(角色卡!V17>=9,"5",IF(角色卡!V17>=7,"4",IF(角色卡!V17>=5,"3",IF(角色卡!V17>=3,"2",IF(角色卡!V17>=2,"1",IF(角色卡!V17="","","0")))))) | AJ17: 项基础以外的武技 | AO17: 基于智慧等级，可习得共计 | AV17: =IF(角色卡!V19>=9,"10",IF(角色卡!V19>=7,"8",IF(角色卡!V19>=5,"6",IF(角色卡!V19>=3,"4",IF(角色卡!V19>=2,"2",IF(角色卡!V19="","","0")))))) | AW17: 项基础以外的术法
AB18: 获得共计 | AI18: =IF(ISBLANK(角色卡!V19),"",IF(角色卡!V19=1,"0",IF(角色卡!V19=2,"1",IF(角色卡!V19=3,"2",IF(角色卡!V19=4,"3",IF(角色卡!V19=5,"4",IF(角色卡!V19=6,"5",IF(角色卡!V19=7,"6",IF(角色卡!V19=8,"7",IF(角色卡!V19=9,"8")))))))))) | AJ18: 点技能点
AB19: =IF(OR(角色卡!V21>=3,角色卡!T26>=12),"获得灵魂武器","未获得灵魂武器") -> 未获得灵魂武器 | AO19: 基于心魂等级，能够拥有 | AV19: =IF(角色卡!V21>=5,"2",IF(角色卡!V21>=3,"1",IF(角色卡!V21="","","0"))) | AW19: 个基础灵能印记
B20: SSS | D20: 8 | F20: 4 | I20: - | O20: 获得1点技能点 | U20: - | AB20: 获得共计 | AI20: =IF(角色卡!T26>=16,"2",IF(角色卡!T26>=10,"1",IF(角色卡!T26="","","0"))) | AJ20: 项专长 | AO20: 获得共计 | AV20: =IF(角色卡!V21>=9,"2",IF(角色卡!V21>=2,"1",IF(角色卡!V21="","","0"))) | AW20: 项灵能力专精
B21: SSS+ | D21: 9 | F21: 4 | I21: 习得1项自选武技 | O21: 习得2项自选术法 获得1点技能点 | U21: 获得1项灵能力专精 | AB21: =IF(角色卡!T26>=14,"可以习得一挡绝技","不可习得一挡绝技") -> 不可习得一挡绝技 | AO21: =IF(角色卡!T26>=18,"可以习得二挡绝技","不可习得二挡绝技") -> 不可习得二挡绝技
AB22: =IF(角色卡!V21>=7,"能够创造一个额外的灵能力标签，并将总字数限制扩展至 100 字","")

Sheet 时髦动作
B2: 时髦动作
B3: 时髦风格 | C3: 消耗 | D3: 动作名和效果 | F3: 五消耗 | G3: 策定山河
B4: 通用 | C4: 50时髦值 | D4: 超灵觉醒-你进行攻击检定时，你通过加骰获得的骰值全部翻倍，然后你投掷一枚 D6，你获得对应数值的经验值。 | F4: 修养身心-在任意时刻，你对自身造成【增加灵力2】。 | G4: 玩世不恭
B5: 策定山河 | C5: 5时髦值 | D5: 修养身心-在任意时刻，你对自身造成【增加灵力2】。 | F5: 加固防御-当你选择防御时，你可以额外投掷 1 枚加骰将结果加入挑战值中。 | G5: 无畏守护
C6: 10时髦值 | D6: 早有预料-你的回合即将开始时，你可以无需消耗行动立即施展一个效果术法。 | F6: 小偷小摸-在任意时刻，你对自身造成【造物1】。 | G6: 快意恩仇
C7: 15时髦值 | D7: 绝代名策-你在进行攻击检定时，如果对方选择反击，你可以获得3枚加骰（仅本次）。 | F7: 磨砺锐气-在任意时刻，你对自身造成【强化攻击1】，你通过此时髦动作获得的【效果】还未失效时，不能再使用该时髦动作。 | G7: 百折不挠
C8: 20时髦值 | D8: 战术切换-新的轮次开始时，对先序的狩魂者造成【强化防御2】，对后序的狩魂者造成【强化攻击2】。 | F8: 呼吸回血-在任意时刻，你对自身造成【恢复1】。 | G8: 组合风格
C9: 25时髦值 | D9: 胜天半子-同场景内的生物进行行动检定成功时（包括你自己），你可以改变本次行动检定获得的【成功等级】，你可以在1~5个【成功等级】中选择。 | F9: 十消耗 | G9: 其他风格
B10: 无畏守护 | C10: 5时髦值 | D10: 加固防御-当你选择防御时，你可以额外投掷 1 枚加骰将结果加入挑战值中。 | F10: 早有预料-你的回合即将开始时，你可以无需消耗行动立即施展一个效果术法。
C11: 10时髦值 | D11: 奋不顾身-其他狩魂者受到单个【效果】时，你可以代替他承受该【效果】。 | F11: 奋不顾身-其他狩魂者受到单个【效果】时，你可以代替他承受该【效果】。
C12: 15时髦值 | D12: 无畏前锋-新的轮次开始时，若你启动该时髦动作，则本轮中，所有敌人的攻击检定必须对你施展。 | F12: 不行重来-你进行一次行动检定后，如果你觉得这次行动检定不符合你的心意，你可以重骰本次行动检定，但你必须接受新的出值与结果。
C13: 20时髦值 | D13: 绝对防御-当前场景中的单一生物受到【伤害】时，你可以令该生物获得对应的【伤害免疫】持续到当前战斗轮结束。 | F13: 刀间舔血-当你选择反击进行攻击检定时，该次检定可以获得2枚加骰。如果你的该次反击的攻击检定小于对方的攻击检定，对方本次进行攻击检定的挑战值减少5点。
C14: 25时髦值 | D14: 永续守护-当你退场时，你可以启动该时髦动作。当前场景中，生物进行行动检定时，你可以为这些行动检定都增加一枚时髦骰。 | F14: 坚韧不拔-在任意时刻，你对自身造成【清除效果2】。
B15: 玩世不恭 | C15: 5时髦值 | D15: 云手摘月-在任意时刻，你对自身造成【造物1】。 | F15: 十五消耗
C16: 10时髦值 | D16: 不行重来-你进行一次行动检定后，如果你觉得这次行动检定不符合你的心意，你可以重骰本次行动检定，但你必须接受新的出值与结果。 | F16: 绝代名策-你在进行攻击检定时，如果对方选择反击，你可以使进行的本次攻击检定获得3枚加骰。
C17: 15时髦值 | D17: 魂灵切换-在任意时刻，你修改你的一个【灵能力标签】并与DH讨论其是否可行，持续到你离开当前场景。 | F17: 无畏前锋-新的轮次开始时，若你启动该时髦动作，则本轮中，所有敌人的攻击检定必须对你施展。
C18: 20时髦值 | D18: 叙事闪回-你在征得DH的同意后，立即向之前曾经历过的事件闪回，寻找这个事件中未曾找到过的细节，或者未曾被注意过的行动。你需要与DH讨论你的闪回事件的具体内容，同时必须让你闪回事件不影响整体的故事走向，或是破坏其他玩家的游戏体验。 | F18: 魂灵切换-在任意时刻，你修改你的一个【灵能力标签】并与DH讨论其是否可行，持续到你离开当前场景。
C19: 25时髦值 | D19: 轮到我了-当一个头目级或首领级生物进入其额外回合时，你可以将其转变为你的额外回合。使用该时髦动作后，你在下个轮次中无法做出任何行动。 | F19: 生死看淡-当你的生命值变为0时，你可以投掷一次D100，如果投掷的数值小于等于你的时髦值两倍，你的生命值变为1点。
B20: 快意恩仇 | C20: 5时髦值 | D20: 磨砺锐气-在任意时刻，你对自身造成【强化攻击1】，你通过此时髦动作获得的【效果】还未失效时，不能再使用该时髦动作。 | F20: 顽强意志-当你的行动检定失败时，你可以将其改为成功，并视为具有1个【成功等级】。
C21: 10时髦值 | D21: 刀间舔血-当你选择反击进行攻击检定时，该次检定可以获得2枚加骰。如果你的该次反击的攻击检定小于对方的攻击检定，对方本次进行攻击检定的挑战值减少5点。 | F21: 二十消耗
C22: 15时髦值 | D22: 生死看淡-当你的生命值变为0时，你可以投掷一次D100，如果投掷的数值小于等于你的时髦值（消耗时髦值前）的两倍，你的生命值变为1点。 | F22: 战术切换-新的轮次开始时，对先序的狩魂者造成【强化防御2】，对后序的狩魂者造成【强化攻击2】。
C23: 20时髦值 | D23: 不服就干-当你的行动检定成功时，你可以消耗X点生命值为该次检定增加x个【成功等级】（X不能大于你的当前生命值）。 | F23: 绝对防御-当前场景中的单一生物受到【伤害】时，你可以令该生物获得对应的【伤害免疫】持续到当前战斗轮结束。
C24: 25时髦值 | D24: 玉石俱焚-当你的生命值变为0时，使你生命值变为0的生物受到【湮灭伤害X】（X等于你的生命值上限）。 | F24: 叙事闪回-你在征得DH的同意后，你开始立即向着之前曾经历过的事件闪回，寻找这个事件中未曾找到过的细节，或者未曾被注意过的行动。 你需要与DH讨论你的闪回事件的具体内容，同时必须让你闪回事件不影响整体的故事走向，或是破坏其他玩家的游戏体验。
B25: 百折不挠 | C25: 5时髦值 | D25: 呼吸回血-在任意时刻，你对自身造成【恢复1】。 | F25: 不服就干-当你的行动检定成功时，你可以消耗X点生命值为该次检定增加X个【成功等级】（X不能大于你的当前生命值）。
C26: 10时髦值 | D26: 坚韧不拔-在任意时刻，你对自身造成【清除效果2】。 | F26: 英雄不朽-你在轮次开始时选择一个已经退场的狩魂者，该狩魂者可以选择消耗20点时髦值重新回到当前场景中，其生命值变为1点。
C27: 15时髦值 | D27: 顽强意志-当你的行动检定失败时，你可以将其改为成功，并视为具有1个【成功等级】。 | F27: 二十五消耗
C28: 20时髦值 | D28: 英雄不朽-你在轮次开始时选择一个已经退场的狩魂者，该狩魂者可以选择消耗20点时髦值重新回到当前场景中，其生命值变为1点。 | F28: 胜天半子-与你在一个场景内的生物进行的行动检定成功时（包括你自己），你可以改变本次行动检定获得的【成功等级】，你可以在1~5个【成功等级】中选择。
C29: 25时髦值 | D29: 生死流转-当你的生命值变为0时，你可以不立即退场，直到你下回合结束后再退场（即使你的生命值不为0）。 | F29: 永续守护-当你退场时，你可以启动该时髦动作。当前场景中，生物进行行动检定时，你可以为这些行动检定都增加一枚时髦骰。
F30: 轮到我了-当一个头目级或首领级生物进入其额外回合时，你可以将其转变为你的额外回合，但如此做后，你在下个轮次中无法做出任何行动。
B31: 如需使用自创风格，请参照上方的格式，将明细填写在下方，并在“角色卡”表的“时髦风格”处选择“其他风格” | F31: 玉石俱焚-当你的生命值变为0时，使你生命值变为0的生物受到【湮灭伤害X】（X等于你的生命值上限）。
B32: 时髦风格 | C32: 消耗 | D32: 动作名和效果 | F32: 生死流转-当你的生命值变为0时，你可以不立即退场，直到你下回合结束后再退场（即使你的生命值不为0）。
C33: 5时髦值
C34: 10时髦值
C35: 15时髦值
C36: 20时髦值
C37: 25时髦值
B39: 如需使用以下拓展风格（或包含了拓展风格的组合风格），请复制单元格内文本后填写至上方空白风格内，随后在“角色卡”表的“时髦风格”处选择“其他风格”
B40: 《边缘人扮演指南》额外时髦动作
B41: 时髦风格 | C41: 消耗 | D41: 动作名和效果
B42: 为所欲为 | C42: 5时髦值 | D42: 横行无忌-在任意时刻，你对场景内单一目标造成【削弱防御1】。
...

Sheet 通用效果
B2: 通用效果速查表
B3: 效果名称 | C3: 效果作用 | D3: 损益性 | E3: 持续性
B4: 恢复 | C4: 增加你X点生命值（X=成功等级） | D4: 正面 | E4: 瞬间效果 | H4: =IF(OR(B4=角色卡!$AK$5,B4=角色卡!$AR$5),"",ROW()) -> 4 | I4: =IF(OR(B4=角色卡!$AK$5,B4=角色卡!$AR$5),"",ROW()) -> 4 | J4: {=IFERROR(INDEX(通用效果!$B:$B,SMALL(通用效果!$H:$H,ROWS(通用效果!$A$4:$A4))),"")} -> 恢复 | K4: {=IFERROR(INDEX(通用效果!$B:$B,SMALL(通用效果!$I:$I,ROWS(通用效果!$A$4:$A4))),"")} -> 恢复
B5: 伤害 | C5: 减少你X点生命值（X=成功等级） | D5: 负面 | E5: 瞬间效果 | H5: =IF(OR(B5=角色卡!$AK$5,B5=角色卡!$AR$5),"",ROW()) -> 5 | I5: =IF(OR(B5=角色卡!$AK$5,B5=角色卡!$AR$5),"",ROW()) -> 5 | J5: {=IFERROR(INDEX(通用效果!$B:$B,SMALL(通用效果!$H:$H,ROWS(通用效果!$A$4:$A5))),"")} -> 伤害 | K5: {=IFERROR(INDEX(通用效果!$B:$B,SMALL(通用效果!$I:$I,ROWS(通用效果!$A$4:$A5))),"")} -> 伤害
B6: 增加灵力 | C6: 你增加X点灵力值（X=成功等级） | D6: 正面 | E6: 瞬间效果 | H6: =IF(OR(B6=角色卡!$AK$5,B6=角色卡!$AR$5),"",ROW()) -> 6 | I6: =IF(OR(B6=角色卡!$AK$5,B6=角色卡!$AR$5),"",ROW()) -> 6 | J6: {=IFERROR(INDEX(通用效果!$B:$B,SMALL(通用效果!$H:$H,ROWS(通用效果!$A$4:$A6))),"")} -> 增加灵力 | K6: {=IFERROR(INDEX(通用效果!$B:$B,SMALL(通用效果!$I:$I,ROWS(通用效果!$A$4:$A6))),"")} -> 增加灵力
B7: 减少灵力 | C7: 你减少X点灵力值（X=成功等级） | D7: 负面 | E7: 瞬间效果 | H7: =IF(OR(B7=角色卡!$AK$5,B7=角色卡!$AR$5),"",ROW()) -> 7 | I7: =IF(OR(B7=角色卡!$AK$5,B7=角色卡!$AR$5),"",ROW()) -> 7 | J7: {=IFERROR(INDEX(通用效果!$B:$B,SMALL(通用效果!$H:$H,ROWS(通用效果!$A$4:$A7))),"")} -> 减少灵力 | K7: {=IFERROR(INDEX(通用效果!$B:$B,SMALL(通用效果!$I:$I,ROWS(通用效果!$A$4:$A7))),"")} -> 减少灵力
B8: 强化攻击 | C8: 直到你下个回合结束时，你下次进行的攻击检定获得 X 枚加骰（X=成功等级） | D8: 正面 | E8: 非瞬间效果 | H8: =IF(OR(B8=角色卡!$AK$5,B8=角色卡!$AR$5),"",ROW()) -> 8 | I8: =IF(OR(B8=角色卡!$AK$5,B8=角色卡!$AR$5),"",ROW()) -> 8 | J8: {=IFERROR(INDEX(通用效果!$B:$B,SMALL(通用效果!$H:$H,ROWS(通用效果!$A$4:$A8))),"")} -> 强化攻击 | K8: {=IFERROR(INDEX(通用效果!$B:$B,SMALL(通用效果!$I:$I,ROWS(通用效果!$A$4:$A8))),"")} -> 强化攻击
B9: 削弱攻击 | C9: 直到你下个回合结束时，你下次进行的攻击检定减少 X 枚加骰（X=成功等级） | D9: 负面 | E9: 非瞬间效果 | H9: =IF(OR(B9=角色卡!$AK$5,B9=角色卡!$AR$5),"",ROW()) -> 9 | I9: =IF(OR(B9=角色卡!$AK$5,B9=角色卡!$AR$5),"",ROW()) -> 9 | J9: {=IFERROR(INDEX(通用效果!$B:$B,SMALL(通用效果!$H:$H,ROWS(通用效果!$A$4:$A9))),"")} -> 削弱攻击 | K9: {=IFERROR(INDEX(通用效果!$B:$B,SMALL(通用效果!$I:$I,ROWS(通用效果!$A$4:$A9))),"")} -> 削弱攻击
B10: 强化防御 | C10: 你的基础防御增加X点（X=成功等级*2） | D10: 正面 | E10: 非瞬间效果 | H10: =IF(OR(B10=角色卡!$AK$5,B10=角色卡!$AR$5),"",ROW()) -> 10 | I10: =IF(OR(B10=角色卡!$AK$5,B10=角色卡!$AR$5),"",ROW()) -> 10 | J10: {=IFERROR(INDEX(通用效果!$B:$B,SMALL(通用效果!$H:$H,ROWS(通用效果!$A$4:$A10))),"")} -> 强化防御 | K10: {=IFERROR(INDEX(通用效果!$B:$B,SMALL(通用效果!$I:$I,ROWS(通用效果!$A$4:$A10))),"")} -> 强化防御
B11: 削弱防御 | C11: 你的基础防御减少X点（X=成功等级*2） | D11: 负面 | E11: 非瞬间效果 | H11: =IF(OR(B11=角色卡!$AK$5,B11=角色卡!$AR$5),"",ROW()) -> 11 | I11: =IF(OR(B11=角色卡!$AK$5,B11=角色卡!$AR$5),"",ROW()) -> 11 | J11: {=IFERROR(INDEX(通用效果!$B:$B,SMALL(通用效果!$H:$H,ROWS(通用效果!$A$4:$A11))),"")} -> 削弱防御 | K11: {=IFERROR(INDEX(通用效果!$B:$B,SMALL(通用效果!$I:$I,ROWS(通用效果!$A$4:$A11))),"")} -> 削弱防御
B12: 清除效果 | C12: 施加该效果的生物选择你身上存在的效果，清除其中的X级效果（X=成功等级） | D12: 正面 | E12: 瞬间效果 | H12: =IF(OR(B12=角色卡!$AK$5,B12=角色卡!$AR$5),"",ROW()) -> 12 | I12: =IF(OR(B12=角色卡!$AK$5,B12=角色卡!$AR$5),"",ROW()) -> 12 | J12: {=IFERROR(INDEX(通用效果!$B:$B,SMALL(通用效果!$H:$H,ROWS(通用效果!$A$4:$A12))),"")} -> 清除效果 | K12: {=IFERROR(INDEX(通用效果!$B:$B,SMALL(通用效果!$I:$I,ROWS(通用效果!$A$4:$A12))),"")} -> 清除效果
B13: 时髦 | C13: 你获得X点时髦值（X=成功等级*2） | D13: 正面 | E13: 瞬间效果 | H13: =IF(OR(B13=角色卡!$AK$5,B13=角色卡!$AR$5),"",ROW()) -> 13 | I13: =IF(OR(B13=角色卡!$AK$5,B13=角色卡!$AR$5),"",ROW()) -> 13 | J13: {=IFERROR(INDEX(通用效果!$B:$B,SMALL(通用效果!$H:$H,ROWS(通用效果!$A$4:$A13))),"")} -> 时髦 | K13: {=IFERROR(INDEX(通用效果!$B:$B,SMALL(通用效果!$I:$I,ROWS(通用效果!$A$4:$A13))),"")} -> 时髦
B14: 叙事 | C14: 如果【成功等级】≥2，你可以按照所期望的方式推动叙事 | D14: 正面 | E14: 瞬间效果 | H14: =IF(OR(B14=角色卡!$AK$5,B14=角色卡!$AR$5),"",ROW()) -> 14 | I14: =IF(OR(B14=角色卡!$AK$5,B14=角色卡!$AR$5),"",ROW()) -> 14 | J14: {=IFERROR(INDEX(通用效果!$B:$B,SMALL(通用效果!$H:$H,ROWS(通用效果!$A$4:$A14))),"")} -> 叙事 | K14: {=IFERROR(INDEX(通用效果!$B:$B,SMALL(通用效果!$I:$I,ROWS(通用效果!$A$4:$A14))),"")} -> 叙事
B15: 获得抗性 | C15: 你获得X层伤害抗性（X=成功等级/2（向下取整）） | D15: 正面 | E15: 非瞬间效果 | H15: =IF(OR(B15=角色卡!$AK$5,B15=角色卡!$AR$5),"",ROW()) -> 15 | I15: =IF(OR(B15=角色卡!$AK$5,B15=角色卡!$AR$5),"",ROW()) -> 15 | J15: {=IFERROR(INDEX(通用效果!$B:$B,SMALL(通用效果!$H:$H,ROWS(通用效果!$A$4:$A15))),"")} -> 获得抗性 | K15: {=IFERROR(INDEX(通用效果!$B:$B,SMALL(通用效果!$I:$I,ROWS(通用效果!$A$4:$A15))),"")} -> 获得抗性
... B18: 造物 | C18: 你获得X点道具点（X=成功等级/2（向下取整）） | D18: 正面 | E18: 瞬间效果 | H18: =IF(OR(B18=角色卡!$AK$5,B18=角色卡!$AR$5),"",ROW()) -> 18 | I18: =IF(OR(B18=角色卡!$AK$5,B18=角色卡!$AR$5),"",ROW()) -> 18 | J18: {=IFERROR(INDEX(通用效果!$B:$B,SMALL(通用效果!$H:$H,ROWS(通用效果!$A$4:$A18))),"")} -> 造物 | K18: {=IFERROR(INDEX(通用效果!$B:$B,SMALL(通用效果!$I:$I,ROWS(通用效果!$A$4:$A18))),"")} -> 造物
H19: =IF(OR(B19=角色卡!$AK$5,B19=角色卡!$AR$5),"",ROW()) -> 19 | I19: =IF(OR(B19=角色卡!$AK$5,B19=角色卡!$AR$5),"",ROW()) -> 19 | J19: {=IFERROR(INDEX(通用效果!$B:$B,SMALL(通用效果!$H:$H,ROWS(通用效果!$A$4:$A19))),"")} | K19: {=IFERROR(INDEX(通用效果!$B:$B,SMALL(通用效果!$I:$I,ROWS(通用效果!$A$4:$A19))),"")}

Sheet 武技
B2: 武技表
B3: 名称 | C3: 消耗 | D3: 目标 | E3: 辅助 | F3: 秘传 | G3: 效果 | H3: 风味描述
B4: 常规武技 | C4: 无 | D4: 单一 | E4: ☑ | F4: ☐ | G4: ·检定成功时，对目标造成【物理伤害】。 | H4: 使用拳脚或武器进行一次常规的攻击。 | J4: =VLOOKUP(角色卡!B39,武技!$B$4:$H$60,6,0)
B5: 转掌 | C5: 2点灵力值 | D5: 单一 | E5: ☐ | F5: ☐ | G5: ·选择反击时进行的攻击检定获得2枚加骰，检定成功时，对自身造成【强化攻击】。 | H5: 步伐如圆转流水，侧移防御攻势的同时调整身位，蓄势反击。 | J5: =VLOOKUP(角色卡!B41,武技!$B$4:$H$60,6,0)
B6: 云手受 | C6: 2点灵力值 | D6: 单一 | E6: ☐ | F6: ☐ | G6: ·选择反击时进行的攻击检定获得4枚加骰，检定成功时，对目标造成【物理伤害】。 | H6: 云手化劲，格挡瞬间借力反击，行云流水无隙可乘。 | J6: =VLOOKUP(角色卡!B43,武技!$B$4:$H$60,6,0)
B7: 太极云手 | C7: 1点灵力值 | D7: 单一 | E7: ☐ | F7: ☐ | G7: ·选择反击时进行的攻击检定获得1枚加骰，检定成功时，对自身造成【恢复灵力1】。 | H7: 以柔克刚，借力化劲，使敌方攻击方向偏移，卸掉劲力。 | J7: =VLOOKUP(角色卡!B45,武技!$B$4:$H$60,6,0)
B8: 鬼步 | C8: 1点灵力值 | D8: 单一 | E8: ☑ | F8: ☐ | G8: ·选择反击时进行的攻击检定获得1枚加骰，检定成功时，对目标造成【物理伤害1】。 | H8: 步法如鬼影迷踪，落步似虚若实。 | J8: =VLOOKUP(角色卡!B47,武技!$B$4:$H$60,6,0)
B9: 霞构 | C9: 1点灵力值 | D9: 单一 | E9: ☑ | F9: ☐ | G9: ·检定成功时，对目标造成【物理伤害】+对自身【霞构】。 【霞构】：【非瞬间效果】【正面】你选择反击进行的攻击检定获得1枚加骰。 | H9: 摆出虚实难辨的防御架势，诱敌冒进，伺机反制其破绽。 | J9: =VLOOKUP(角色卡!B49,武技!$B$4:$H$60,6,0)
B10: 无想剑 | C10: 2点灵力值 | D10: 单一 | E10: ☑ | F10: ☐ | G10: ·检定成功时，对目标造成【物理伤害2】+对自身造成【无想剑】。 【无想剑】：【非瞬间效果】【正面】你下次施展武技进行攻击检定的定骰视掷出19，然后结束本效果。 | H10: 摒弃杂念进入无我之境，心神合一锁定敌之破绽，下一击必中要害。 | J10: =VLOOKUP(角色卡!B51,武技!$B$4:$H$60,6,0)
B11: 铁骑当 | C11: 2点灵力值 | D11: 单一 | E11: ☑ | F11: ☐ | G11: ·检定成功时，对目标造成【物理伤害】+对自身造成【铁壁】。 【铁壁】：【非瞬间效果】【正面】其他生物对你施展武技进行攻击检定成功时获得的成功等级减少2个，你施展武技进行攻击检定的成功等级增加2个。 | H11: 沉腰立马如铁骑磐石，降低重心抵御冲撞，稳若山岳。 | J11: =VLOOKUP(角色卡!B53,武技!$B$4:$H$60,6,0)
B12: 天罡步 | C12: 2点灵力值 | D12: 单一 | E12: ☐ | F12: ☐ | G12: ·进行攻击检定获得1枚加骰，该次攻击的目标无法选择反击，检定成功时，对目标造成【物理伤害】。 | H12: 踏北斗七星位，行动轨迹难以预测。 | J12: =VLOOKUP(角色卡!B55,武技!$B$4:$H$60,6,0)
B13: 瞬剑斩 | C13: 2点灵力值 | D13: 单一 | E13: ☑ | F13: ☐ | G13: ·检定成功时，对目标造成【物理伤害】+如果目标具有【物理易伤】则额外造成【物理伤害2】。 | H13: 刀不出鞘则静若深渊，出鞘刹那寒光裂空，以极致速度完成一击必杀。 | J13: =VLOOKUP(角色卡!B57,武技!$B$4:$H$60,6,0)
B14: 血怒 | C14: 2点灵力值 | D14: 单一 | E14: ☐ | F14: ☐ | G14: ·检定成功时，对目标造成【物理伤害】+如果你已损失生命值，额外造成【火焰伤害2】。 | H14: 伤痛激发狂暴血性，伤势越重则战意越凶，以血还血以命搏命。 | J14: =VLOOKUP(角色卡!B59,武技!$B$4:$H$60,6,0)
B15: 胧月夜 | C15: 2点灵力值 | D15: 单一 | E15: ☑ | F15: ☐ | G15: ·检定成功时，对目标造成【物理伤害2】。 ·成功等级≥2时，再对目标造成2次【物理伤害1】。 | H15: 剑影如胧月倾泻，虚实交替的连续斩击封锁敌人进退之路。 | J15: =VLOOKUP(角色卡!B61,武技!$B$4:$H$60,6,0)
B16: 般若掌 | C16: 2点灵力值 | D16: 单一 | E16: ☐ | F16: ☐ | G16: ·该攻击检定承受5点减值，检定成功时，对目标造成【物理伤害2】+【灵识伤害2】。 | H16: 内力凝于掌心，掌风如浪潮般汹涌外放，三丈内隔空伤敌。 | J16: =VLOOKUP(角色卡!B63,武技!$B$4:$H$60,6,0)
B17: 逆卷刃 | C17: 2点灵力值 | D17: 单一 | E17: ☑ | F17: ☐ | G17: ·检定成功时，对目标造成【物理伤害】+如果目标本轮已进行过行动，额外造成【冰霜伤害2】。 | H17: 刀势骤转，反手逆劈如逆浪回卷，攻敌不备之死角。 | J17: =VLOOKUP(角色卡!B65,武技!$B$4:$H$60,6,0)
B18: 雷霆劈 | C18: 3点灵力值 | D18: 单一 | E18: ☑ | F18: ☐ | G18: ·检定成功时，对目标造成【物理伤害】+【雷电伤害】。 | H18: 双手持剑蓄力重劈，如雷霆贯地，刚猛劲力可碎金石。 | J18: =VLOOKUP(角色卡!B67,武技!$B$4:$H$60,6,0)
B19: 符剑术 | C19: 2点灵力值 | D19: 单一 | E19: ☐ | F19: ☐ | G19: ·检定成功时，对目标造成【物理伤害1】+如果目标是鬼魂，对目标额外造成【灵识伤害3】。 | H19: 以剑为笔凌空画符，剑气裹挟破邪之力，专克阴邪之物。 | J19: =VLOOKUP(角色卡!B69,武技!$B$4:$H$60,6,0)
B20: 形意·虎扑炮锤 | C20: 3点灵力值 | D20: 单一 | E20: ☑ | F20: ☐ | G20: ·检定成功时，对目标造成【物理伤害】+【物理伤害】。 | H20: 仿猛虎扑食之势，双手成爪虚晃，突然以肘击直取心窝，附带内劲穿透。 | J20: =VLOOKUP(角色卡!B71,武技!$B$4:$H$60,6,0)
B21: 八步赶蝉 | C21: 2点灵力值 | D21: 单一 | E21: ☐ | F21: ☐ | G21: ·检定成功时，对目标造成【物理伤害1】+你可以额外消耗（X）点灵力点（X最大为5，最小为1）对目标造成【物理伤害X】。 | H21: 瞬间突进，如飞蝉掠空，快速突破重重包围，取敌首级。 | J21: =VLOOKUP(角色卡!B73,武技!$B$4:$H$60,6,0)
B22: 醉仙望月 | C22: 2点灵力值 | D22: 单一 | E22: ☐ | F22: ☐ | G22: ·检定成功时，对目标造成【物理伤害3】。 | H22: 步伐踉跄如醉汉望月，身形摇晃间暗藏杀机，诱敌轻敌后骤然发难。
B23: 骗击 | C23: 2点灵力值 | D23: 单一 | E23: ☑ | F23: ☐ | G23: ·如果目标选择反击，进行的攻击检定获得3枚加骰。检定成功时，对目标造成【物理伤害】。 | H23: 虚招佯攻诱敌防御，骤然变招直取破绽，虚实交错间克敌制胜。
B24: 天地摔 | C24: 2点灵力值 | D24: 单一 | E24: ☐ | F24: ☐ | G24: ·检定成功时，对目标造成【物理伤害2】+对目标造成【失衡】+对自身造成【失衡】。 【失衡】：【非瞬间效果】【负面】你下次受到【物理伤害】时，对你造成【物理伤害1】，然后终止本效果。 | H24: 借敌之力破坏其重心，如天地倒悬般将敌摔落，致其筋骨失衡。
B25: 形意·鹰捉劈挂 | C25: 2点灵力值 | D25: 单一 | E25: ☑ | F25: ☐ | G25: ·目标选择防御时，进行的攻击检定获得3枚加骰。检定成功时，对目标造成【物理伤害】。 | H25: 如鹰隼擒拿，先以爪功缩敌关节，再衔接劈掌砸击，专破防守姿态。
B26: 影舞乱花 | C26: 1点灵力值 | D26: 1~3个 | E26: ☐ | F26: ☐ | G26: ·检定成功时，对目标造成【清除效果】。 | H26: 忍步疾走间双手飞扬，飞镖、铁蒺藜如乱花骤雨，封敌进退之路。
B27: 九转还丹劲 | C27: 3点灵力值 | D27: 单一 | E27: ☐ | F27: ☐ | G27: ·进行攻击检定获得3枚加骰。检定成功时，对目标造成【物理伤害】+对自身造成【恢复】。 | H27: 受伤后运转周天，缓慢恢复体力。
B28: 蛇咬 | C28: 1点灵力值 | D28: 单一 | E28: ☐ | F28: ☐ | G28: ·检定成功时，对目标造成【物理伤害】+【灵蛇毒】。 【灵蛇毒】：【非瞬间效果】【负面】你消耗灵力值时，对你造成【灵识伤害1】，然后终止本效果。 | H28: 出手时如蛇信吐芯，专取敌人关节、颈侧等要害。
B29: 残影 | C29: 3点灵力值 | D29: 单一 | E29: ☐ | F29: ☐ | G29: ·检定成功时，对目标造成【物理伤害】+对自身【强化防御1】+创造场景标签【残影】。 | H29: 攻击时留下残影
B30: 浴血 | C30: 2点灵力值 | D30: 单一 | E30: ☐ | F30: ☐ | G30: ·进行攻击检定获得X枚加骰（X=已损失生命值/2（向下取整）），检定成功时，对目标造成【物理伤害】。 | H30: 以伤换势，血脉逆行仿佛沸腾。
B31: 瞬身击 | C31: 1点灵力值 | D31: 1~3个 | E31: ☑ | F31: ☐ | G31: ·检定成功时，对目标造成【物理伤害】。 | H31: 灵识汇聚足下，瞬间欺进敌身。
B32: 凿金功 | C32: 3点灵力值 | D32: 单一 | E32: ☐ | F32: ☐ | G32: ·检定成功时，对目标造成【物理伤害】+【赋予物理易伤】+【赋予灵识易伤】。 | H32: 灵识聚于一处洞穿坚甲，让敌手如遭重锤凿击。
B33: 虎啸 | C33: 1点灵力值 | D33: 单一 | E33: ☐ | F33: ☐ | G33: ·检定成功时，对目标造成【雷电伤害】+【赋予雷电易伤】。 | H33: 以迅猛的力量突破空气，伴随着震耳欲聋的空气爆破声产生巨大的冲击力。
... B59: 形意·鼍形翻浪劲 | C59: 4点灵力值 | D59: 单一 | E59: ☐ | F59: ☑ | G59: ·检定成功时，对目标造成【物理伤害 3】+对自身造成【获得物理抗性 2】+【获得灵识抗性 2】+【获得火焰抗性 2】+【获得雷电抗性 2】+【获得冰霜抗性 2】。 | H59: 双臂如鼍翻浪，格挡同时反手抽打，攻防一体。

Sheet 术法
B2: 术法表
B3: 名称 | C3: 消耗 | D3: 目标 | E3: 类别 | F3: 秘传 | G3: 类型 | H3: 效果 | I3: 风味描述
B4: 超感 | C4: 2点灵力值 | D4: 自身 | E4: 基础 | F4: ☐ | G4: 效果术法 | H4: ·对自身造成【超感】直到当前场景结束。 【超感】：【非瞬间效果】【正面】你进行的调查检定获得 2 枚加骰。 | I4: 灵识聚拢在双目，瞳孔流转淡蓝的微光，看到不被注意的细节。 | K4: =VLOOKUP(角色卡!AR41,术法!$B$4:$I$133,7,0)
B5: 凝爆 | C5: 2点灵力值 | D5: 单一 | E5: 基础 | F5: ☐ | G5: 攻击术法【体魄】 | H5: ·检定成功时，对目标造成【灵识伤害 2】。 | I5: 凝聚浑身灵识后引爆周身。 | K5: =VLOOKUP(角色卡!AR43,术法!$B$4:$I$133,7,0)
B6: 灵迹 | C6: 无 | D6: 自身 | E6: 基础 | F6: ☐ | G6: 效果术法 | H6: ·对自身造成【灵迹】持续到事件结束。 【灵迹】：【非瞬间效果】【正面】你可以读取/留下场景中只有觉醒灵识者才能看到的痕迹。 | I6: 灵力留下的痕迹将在你的双目当中闪烁淡蓝荧光。 | K6: =VLOOKUP(角色卡!AR39,术法!$B$4:$I$133,7,0)
B7: 安宅符 | C7: 无 | D7: 场景 | E7: 符箓 | F7: ☐ | G7: 效果术法 | H7: ·你可以立即知道场景中是否存在【鬼魂】类型的生物。 | I7: 黄纸朱砂绘制，贴于门楣可阻寻常邪祟入宅。若遇阴物靠近，符角会自行卷曲示警。 | K7: =VLOOKUP(角色卡!AR45,术法!$B$4:$I$133,7,0)
B8: 和合帖 | C8: 2点灵力值 | D8: 单一 | E8: 符箓 | F8: ☐ | G8: 效果术法 | H8: ·你与自愿的目标订下契约，契约的内容是一个双方都认可的约定，如果一方违反了这个约定，另外一方就会知晓。 | I8: 并蒂莲花汁液书写，夫妻各持半张。若一方变心，符纸会逐渐褪色成灰白。 | K8: =VLOOKUP(角色卡!AR47,术法!$B$4:$I$133,7,0)
B9: 文昌签 | C9: 2点灵力值 | D9: 单一 | E9: 符箓 | F9: ☐ | G9: 效果术法 | H9: ·你为自愿的目标贴下【袖签】持续到当前事件结束。 【袖签】：【非瞬间效果】你施展武技或者术法时，受到【火焰伤害 3】，然后终止本效果。 | I9: 用状元曾用的毛笔蘸墨书写，考试时藏在袖中。作弊时会突然发烫灼伤手腕。 | K9: =VLOOKUP(角色卡!AR49,术法!$B$4:$I$133,7,0)
B10: 避水诀 | C10: 1点灵力值 【维持】 | D10: 单一 | E10: 符箓 | F10: ☐ | G10: 效果术法 | H10: ·对自愿的目标造成【获得冰霜抗性 1】。 | I10: 鱼鳔胶混合辰砂制成，贴在衣领内侧。入水后会在口鼻处形成气泡，但最多维持半刻 钟。 | K10: =VLOOKUP(角色卡!AR51,术法!$B$4:$I$133,7,0)
B11: 五谷符 | C11: 2点灵力值 | D11: 场景 | E11: 符箓 | F11: ☐ | G11: 效果术法 | H11: ·你可以立即得知场景中是否有蕴含有毒物质。 | I11: 埋在粮仓四角的黄符，能驱粮虫鼠蚁。丰收时符上会浮现麦穗纹路。 | K11: =VLOOKUP(角色卡!AR53,术法!$B$4:$I$133,7,0)
B12: 寻踪引 | C12: 2点灵力值 | D12: 自身 | E12: 符箓 | F12: ☐ | G12: 效果术法 | H12: ·你指向一件你见过的目标，只要这个目标存在，你就能知道这个物件目标你模糊的方向。 *该目标一定得是【生物】。 | I12: 取失踪者头发烧灰入符。点燃后青烟所指即为其所在方向，但遇风雨易散。 | K12: =VLOOKUP(角色卡!AR55,术法!$B$4:$I$133,7,0)
B13: 镇啼咒 | C13: 2点灵力值 | D13: 场景 | E13: 符箓 | F13: ☐ | G13: 效果术法 | H13: ·你可以立即知道场景中是否存在【鬼魂】类型的生物，并且得知那些生物的位置。 | I13: 乌鸦尾羽蘸雄黄酒书写，贴于婴儿床头。若仍夜啼不止，说明屋内有游魂作祟。 | K13: =VLOOKUP(角色卡!AR57,术法!$B$4:$I$133,7,0)
B14: 化煞帖 | C14: 2点灵力值 | D14: 场景 | E14: 符箓 | F14: ☐ | G14: 效果术法 | H14: ·你可以阻止【鬼魂】类型的生物进入该场景，直到事件结束。如【鬼魂】类型的生物试图强行闯入，会受到【灵识伤害 2】。 | I14: 贴在房梁或尖角处，能化解冲煞。煞气越重，符纸腐烂的速度就越快。 | K14: =VLOOKUP(角色卡!AR59,术法!$B$4:$I$133,7,0)
B15: 行车护 | C15: 2点灵力值 | D15: 单一 | E15: 符箓 | F15: ☐ | G15: 效果术法 | H15: ·你为自愿的目标设下保护，目标获得【护体】持续到你离开当前场景。 【护体】：【非瞬间效果】【正面】你受到【伤害】时，该【伤害】减少 1 级，在【护体】成功为你累积减少 3 级效果等级后，终止本效果。 | I15: 马王爷画像拓印，贴在车辕上。遇险前会听见马嘶预警，仅限三次。 | K15: =VLOOKUP(角色卡!AR61,术法!$B$4:$I$133,7,0)
B16: 祛瘟散 | C16: 2点灵力值 | D16: 单一 | E16: 符箓 | F16: ☐ | G16: 攻击术法【心魂】 | H16: ·检定成功时，如果目标是【鬼魂】生物，对目标造成【灵识伤害 5】。 | I16: 艾草灰混合朱砂，焚烧后的烟可净化疫气。但每用一次要更换门前的菖蒲。 | K16: =VLOOKUP(角色卡!AR63,术法!$B$4:$I$133,7,0)
B17: 梦通符 | C17: 1点灵力值 | D17: 自身 | E17: 符箓 | F17: ☐ | G17: 效果术法 | H17: ·恍惚的梦境中，你窥见命运的一隅，你预测后事的吉凶，梦会回答。若梦不作答，则吉凶皆有。 | I17: 狐仙庙供过的黄纸，枕于床榻。能梦示吉凶，但可能招来狐仙窥探隐私。 | K17: =VLOOKUP(角色卡!AR65,术法!$B$4:$I$133,7,0)
B18: 捆塞符 | C18: 2点灵力值 【维持】 | D18: 单一 | E18: 符箓 | F18: ☐ | G18: 攻击术法【体魄】 | H18: ·检定成功时，对目标造成【捆缚】。 【捆缚】：【非瞬间效果】【负面】你选择防御时无法激活标签。 | I18: 用金粉所书写的黄符，能够化为一道金光捆绑目标。 | K18: =VLOOKUP(角色卡!AR67,术法!$B$4:$I$133,7,0)
B19: 见心符 | C19: 1点灵力值 | D19: 单一，目标必须是【鬼魂】生物 | E19: 符箓 | F19: ☐ | G19: 攻击术法【智慧】 | H19: ·检定成功时，你能听到目标的表面思想。 | I19: 取一滴泪珠混合朱砂，贴在他人额头能够窥探其心中所想。 | K19: =VLOOKUP(角色卡!AR69,术法!$B$4:$I$133,7,0)
B20: 断空符 | C20: 2点灵力值 | D20: 场景 | E20: 符箓 | F20: ☐ | G20: 效果术法 | H20: ·创建场景标签【空气墙】持续到你离开当前场景。 | I20: 凝聚灵力于符箓当中，挥至空中，能够构筑无形气墙，封锁区域阻碍通行。 | K20: =VLOOKUP(角色卡!AR71,术法!$B$4:$I$133,7,0)
B21: 招雾符 | C21: 2点灵力值 | D21: 场景 | E21: 符箓 | F21: ☐ | G21: 效果术法 | H21: ·创建场景标签【浓雾】持续到你离开当前场景。 | I21: 点燃符箓燃起青烟，召来厚重浓雾弥漫战场，遮蔽视线干扰行动。 | K21: =VLOOKUP(角色卡!AR73,术法!$B$4:$I$133,7,0)
B22: 御魔符 | C22: 1点灵力值 | D22: 特殊 | E22: 符箓 | F22: ☐ | G22: 效果术法 | H22: ·用一张符箓贴在1件你指定的小型物件上，该物件当即被活化；被活化的物件又或是你指示的小型生物会在一定时间内成为你的使魔。 ·你可以吩咐使魔一道简单的指令，比如监视某人、跟踪某人、把守某地等等。每有1点消耗，使魔就持续活动1小时。 ·如果使用道具点施展此符咒，那使魔可以持续活动 3 小时而非 1 小时。 ·直到持续时间结束前，使魔将尽可能按照你的指令行动。 ·如果使魔终止活动或在持续时间前被消灭，你可以得知这段时间内使魔知道的所有信息。 | I22: 将符箓融至水中，用符水点化小物或小兽，令其听令执行简单任务，并能获悉其见闻。
B23: 追雀符 | C23: 1点灵力值 | D23: 单一 | E23: 符箓 | F23: ☐ | G23: 效果术法 | H23: ·你将一道隐形的能量符咒赋予一个无灵识的目标。你可以感知和追踪到符咒的位置，持续到事件结束。 | I23: 运用灵力凌空构建符箓，可悄无声息于目标身上施放追踪印记，无论天涯海角，皆可感知其方位。
B24: 缠火符 | C24: 1点灵力值 【维持】 | D24: 单一 | E24: 符箓 | F24: ☐ | G24: 效果术法 | H24: ·对自愿的目标造成【火象】。 【火象】：【非瞬间效果】【正面】你施展武技造成【伤害】时，可以全部转化成【火焰伤害】。 | I24: 赋予自愿者火之气息，令其武技尽数化为烈焰之击。
B25: 冰牙符 | C25: 1点灵力值 【维持】 | D25: 单一 | E25: 符箓 | F25: ☐ | G25: 效果术法 | H25: ·对自愿的目标造成【冰象】。 【冰象】：【非瞬间效果】【正面】你施展武技造成【伤害】时，可以全部转化成【冰霜伤害】。 | I25: 赋予自愿者冰之气息，令其武技尽数化为寒冰之击。
B26: 滚雷符 | C26: 1点灵力值 【维持】 | D26: 单一 | E26: 符箓 | F26: ☐ | G26: 效果术法 | H26: ·对自愿的目标造成【雷象】。 【雷象】：【非瞬间效果】【正面】你施展武技造成【伤害】时，可以全部转化成【雷电伤害】。 | I26: 赋予自愿者雷之气息，令其武技尽数化为雷电之击。
B27: 灵破符 | C27: 1点灵力值 【维持】 | D27: 单一 | E27: 符箓 | F27: ☐ | G27: 效果术法 | H27: ·对自愿的目标造成【灵象】。 【灵象】：【非瞬间效果】【正面】你施展武技造成【伤害】时，可以全部转化成【灵识伤害】。 | I27: 赋予自愿者灵识之力，令其武技尽数化为冲击精神的灵识之伤。
B28: 隐身符 | C28: 1点灵力值 【维持】 | D28: 单一 | E28: 符箓 | F28: ☐ | G28: 效果术法 | H28: ·对自愿的目标造成【神隐】。 【神隐】：【非瞬间效果】【正面】你进行的隐秘检定成功时，获得的【成功等级】增加 1 个。你选择防御时，可以额外投掷一枚 D4 骰将结果加入基础防御中。 | I28: 助自愿者遁入神隐之境，大幅强化潜行能力，其力量也能够护佑神隐者。
B29: 铜镜符 | C29: 1点灵力值 【维持】 | D29: 单一 | E29: 符箓 | F29: ☐ | G29: 效果术法 | H29: ·对自愿的目标造成【神盾镜】。 【神盾镜】：【非瞬间效果】【正面】当你因为其他生物对你造成的【效果】而减少生命值时，你可以让其不生效，并使对你造成【效果】的目标减少相同的生命值，然后终止本效果。 | I29: 为自愿者施加神盾之镜，可将一次来袭伤害反射至施害者身上，随即消散于天地。
B30: 符钉 | C30: 3点灵力值 【维持】 | D30: 单一 | E30: 符箓 | F30: ☐ | G30: 攻击术法【心魂】 | H30: ·该术法进行的攻击检定无法被反击。 ·检定成功时，对目标造成【钉身】。 【钉身】：【非瞬间效果】【负面】你无法选择反击，当你受到非【钉身】造成的【伤害】时，额外受到【灵识伤害1】。 | I30: 以灵力凝聚符钉射向目标，命中后压制其反击能力，并使其持续承受灵识之苦。
B31: 烟遁符 | C31: 1点灵力值 | D31: 单一 | E31: 符箓 | F31: ☐ | G31: 效果术法 | H31: ·对自愿的目标移出非战斗场景。 | I31: 瞬间以烟雾包裹自愿目标，助其脱离危险之境。
B32: 风吹符 | C32: 2点灵力值 | D32: 自身 | E32: 符箓 | F32: ☐ | G32: 效果术法 | H32: ·对自身造成【风暴化身】持续到你离开当前场景。 【风暴化身】：【非瞬间效果】【正面】你的身边缠绕巨大的旋风。你可以操纵旋风用于飞行。 ·你可以执行行动选择单一目标，视为施展一个攻击术法【体魄】进行一次攻击检定，检定成功时，对目标造成【雷电伤害 5】。 | I32: 唤来风暴缠身，赋予施术者驾驭旋风飞行的能力，亦可驱使风雷之力轰击敌人。
B33: 摘星符 | C33: 1点灵力值 | D33: 单一 | E33: 符箓 | F33: ☐ | G33: 攻击术法【体魄】 | H33: ·该术法进行的攻击检定无法被反击。 ·检定成功时，你指定一件你可以单手持握的物品，从视线内/目标的手中飞到你的手中。 | I33: 将符箓化为无形之手，无论强行夺取目标手中之物，或招来视线内小件物品，皆易如反掌。
... B132: 七星灯续命阵 | C132: 7点灵力值 | D132: 单一 | E132: 阵法 | F132: ☑ | G132: 效果术法 | H132: ·你选择一个已经退场的生物，让他以 X 点生命值回到当前场景中。 ·消耗额外灵力值为 0 时：X=1 ·消耗额外灵力值为 7 时：X=3 ·消耗额外灵力值为 14 时：X=5 ·消耗额外灵力值为 21 时：X=7 | I132: 七星灯阵借北斗星辰之力，逆天改命。七盏青铜灯按北斗排列，鲛人油燃魂火，紫檀香引神念。施术者坐镇北极，七日不灭则寿延一纪。然灯火摇曳，一息不慎，便是魂飞魄散，永世不得超生。

Sheet 灵能印记
B2: 灵能印记表
B3: 印记 类型 | C3: 描述
B4: 缩小 | C4: 武器可以随你想法变小 | E4: =IF(OR(B4=角色卡!$BD$22,B4=角色卡!$BH$22,B4=角色卡!$BD$24,B4=角色卡!$BH$24),"",ROW()) -> 4 | F4: =IF(OR(B4=角色卡!$BD$22,B4=角色卡!$BH$22,B4=角色卡!$BD$24,B4=角色卡!$BH$24),"",ROW()) -> 4 | G4: =IF(OR(B4=角色卡!$BD$22,B4=角色卡!$BH$22,B4=角色卡!$BD$24,B4=角色卡!$BH$24),"",ROW()) -> 4 | H4: =IF(OR(B4=角色卡!$BD$22,B4=角色卡!$BH$22,B4=角色卡!$BD$24,B4=角色卡!$BH$24),"",ROW()) -> 4 | I4: {=IFERROR(INDEX(灵能印记!$B:$B,SMALL(灵能印记!$E:$E,ROWS(灵能印记!$A$4:$A4))),"")} -> 缩小 | J4: {=IFERROR(INDEX(灵能印记!$B:$B,SMALL(灵能印记!$F:$F,ROWS(灵能印记!$A$4:$A4))),"")} -> 缩小 | K4: {=IFERROR(INDEX(灵能印记!$B:$B,SMALL(灵能印记!$G:$G,ROWS(灵能印记!$A$4:$A4))),"")} -> 缩小 | L4: {=IFERROR(INDEX(灵能印记!$B:$B,SMALL(灵能印记!$H:$H,ROWS(灵能印记!$A$4:$A4))),"")} -> 缩小
B5: 放大 | C5: 武器可以随你想法变大 | E5: =IF(OR(B5=角色卡!$BD$22,B5=角色卡!$BH$22,B5=角色卡!$BD$24,B5=角色卡!$BH$24),"",ROW()) -> 5 | F5: =IF(OR(B5=角色卡!$BD$22,B5=角色卡!$BH$22,B5=角色卡!$BD$24,B5=角色卡!$BH$24),"",ROW()) -> 5 | G5: =IF(OR(B5=角色卡!$BD$22,B5=角色卡!$BH$22,B5=角色卡!$BD$24,B5=角色卡!$BH$24),"",ROW()) -> 5 | H5: =IF(OR(B5=角色卡!$BD$22,B5=角色卡!$BH$22,B5=角色卡!$BD$24,B5=角色卡!$BH$24),"",ROW()) -> 5 | I5: {=IFERROR(INDEX(灵能印记!$B:$B,SMALL(灵能印记!$E:$E,ROWS(灵能印记!$A$4:$A5))),"")} -> 放大 | J5: {=IFERROR(INDEX(灵能印记!$B:$B,SMALL(灵能印记!$F:$F,ROWS(灵能印记!$A$4:$A5))),"")} -> 放大 | K5: {=IFERROR(INDEX(灵能印记!$B:$B,SMALL(灵能印记!$G:$G,ROWS(灵能印记!$A$4:$A5))),"")} -> 放大 | L5: {=IFERROR(INDEX(灵能印记!$B:$B,SMALL(灵能印记!$H:$H,ROWS(灵能印记!$A$4:$A5))),"")} -> 放大
B6: 柔软 | C6: 武器可以变得柔软 | E6: =IF(OR(B6=角色卡!$BD$22,B6=角色卡!$BH$22,B6=角色卡!$BD$24,B6=角色卡!$BH$24),"",ROW()) -> 6 | F6: =IF(OR(B6=角色卡!$BD$22,B6=角色卡!$BH$22,B6=角色卡!$BD$24,B6=角色卡!$BH$24),"",ROW()) -> 6 | G6: =IF(OR(B6=角色卡!$BD$22,B6=角色卡!$BH$22,B6=角色卡!$BD$24,B6=角色卡!$BH$24),"",ROW()) -> 6 | H6: =IF(OR(B6=角色卡!$BD$22,B6=角色卡!$BH$22,B6=角色卡!$BD$24,B6=角色卡!$BH$24),"",ROW()) -> 6 | I6: {=IFERROR(INDEX(灵能印记!$B:$B,SMALL(灵能印记!$E:$E,ROWS(灵能印记!$A$4:$A6))),"")} -> 柔软 | J6: {=IFERROR(INDEX(灵能印记!$B:$B,SMALL(灵能印记!$F:$F,ROWS(灵能印记!$A$4:$A6))),"")} -> 柔软 | K6: {=IFERROR(INDEX(灵能印记!$B:$B,SMALL(灵能印记!$G:$G,ROWS(灵能印记!$A$4:$A6))),"")} -> 柔软 | L6: {=IFERROR(INDEX(灵能印记!$B:$B,SMALL(灵能印记!$H:$H,ROWS(灵能印记!$A$4:$A6))),"")} -> 柔软
B7: 坚硬 | C7: 武器可以变得坚硬 | E7: =IF(OR(B7=角色卡!$BD$22,B7=角色卡!$BH$22,B7=角色卡!$BD$24,B7=角色卡!$BH$24),"",ROW()) -> 7 | F7: =IF(OR(B7=角色卡!$BD$22,B7=角色卡!$BH$22,B7=角色卡!$BD$24,B7=角色卡!$BH$24),"",ROW()) -> 7 | G7: =IF(OR(B7=角色卡!$BD$22,B7=角色卡!$BH$22,B7=角色卡!$BD$24,B7=角色卡!$BH$24),"",ROW()) -> 7 | H7: =IF(OR(B7=角色卡!$BD$22,B7=角色卡!$BH$22,B7=角色卡!$BD$24,B7=角色卡!$BH$24),"",ROW()) -> 7 | I7: {=IFERROR(INDEX(灵能印记!$B:$B,SMALL(灵能印记!$E:$E,ROWS(灵能印记!$A$4:$A7))),"")} -> 坚硬 | J7: {=IFERROR(INDEX(灵能印记!$B:$B,SMALL(灵能印记!$F:$F,ROWS(灵能印记!$A$4:$A7))),"")} -> 坚硬 | K7: {=IFERROR(INDEX(灵能印记!$B:$B,SMALL(灵能印记!$G:$G,ROWS(灵能印记!$A$4:$A7))),"")} -> 坚硬 | L7: {=IFERROR(INDEX(灵能印记!$B:$B,SMALL(灵能印记!$H:$H,ROWS(灵能印记!$A$4:$A7))),"")} -> 坚硬
B8: 轻便 | C8: 武器对于你来说很轻便，即使其外观看起来不是这样 | E8: =IF(OR(B8=角色卡!$BD$22,B8=角色卡!$BH$22,B8=角色卡!$BD$24,B8=角色卡!$BH$24),"",ROW()) -> 8 | F8: =IF(OR(B8=角色卡!$BD$22,B8=角色卡!$BH$22,B8=角色卡!$BD$24,B8=角色卡!$BH$24),"",ROW()) -> 8 | G8: =IF(OR(B8=角色卡!$BD$22,B8=角色卡!$BH$22,B8=角色卡!$BD$24,B8=角色卡!$BH$24),"",ROW()) -> 8 | H8: =IF(OR(B8=角色卡!$BD$22,B8=角色卡!$BH$22,B8=角色卡!$BD$24,B8=角色卡!$BH$24),"",ROW()) -> 8 | I8: {=IFERROR(INDEX(灵能印记!$B:$B,SMALL(灵能印记!$E:$E,ROWS(灵能印记!$A$4:$A8))),"")} -> 轻便 | J8: {=IFERROR(INDEX(灵能印记!$B:$B,SMALL(灵能印记!$F:$F,ROWS(灵能印记!$A$4:$A8))),"")} -> 轻便 | K8: {=IFERROR(INDEX(灵能印记!$B:$B,SMALL(灵能印记!$G:$G,ROWS(灵能印记!$A$4:$A8))),"")} -> 轻便 | L8: {=IFERROR(INDEX(灵能印记!$B:$B,SMALL(灵能印记!$H:$H,ROWS(灵能印记!$A$4:$A8))),"")} -> 轻便
B9: 沉重 | C9: 武器对于他人来说很沉重，难以正常握持或挥动 | E9: =IF(OR(B9=角色卡!$BD$22,B9=角色卡!$BH$22,B9=角色卡!$BD$24,B9=角色卡!$BH$24),"",ROW()) -> 9 | F9: =IF(OR(B9=角色卡!$BD$22,B9=角色卡!$BH$22,B9=角色卡!$BD$24,B9=角色卡!$BH$24),"",ROW()) -> 9 | G9: =IF(OR(B9=角色卡!$BD$22,B9=角色卡!$BH$22,B9=角色卡!$BD$24,B9=角色卡!$BH$24),"",ROW()) -> 9 | H9: =IF(OR(B9=角色卡!$BD$22,B9=角色卡!$BH$22,B9=角色卡!$BD$24,B9=角色卡!$BH$24),"",ROW()) -> 9 | I9: {=IFERROR(INDEX(灵能印记!$B:$B,SMALL(灵能印记!$E:$E,ROWS(灵能印记!$A$4:$A9))),"")} -> 沉重 | J9: {=IFERROR(INDEX(灵能印记!$B:$B,SMALL(灵能印记!$F:$F,ROWS(灵能印记!$A$4:$A9))),"")} -> 沉重 | K9: {=IFERROR(INDEX(灵能印记!$B:$B,SMALL(灵能印记!$G:$G,ROWS(灵能印记!$A$4:$A9))),"")} -> 沉重 | L9: {=IFERROR(INDEX(灵能印记!$B:$B,SMALL(灵能印记!$H:$H,ROWS(灵能印记!$A$4:$A9))),"")} -> 沉重
B10: 失衡 | C10: 武器可以用来干扰敌人或是制造破绽 | E10: =IF(OR(B10=角色卡!$BD$22,B10=角色卡!$BH$22,B10=角色卡!$BD$24,B10=角色卡!$BH$24),"",ROW()) -> 10 | F10: =IF(OR(B10=角色卡!$BD$22,B10=角色卡!$BH$22,B10=角色卡!$BD$24,B10=角色卡!$BH$24),"",ROW()) -> 10 | G10: =IF(OR(B10=角色卡!$BD$22,B10=角色卡!$BH$22,B10=角色卡!$BD$24,B10=角色卡!$BH$24),"",ROW()) -> 10 | H10: =IF(OR(B10=角色卡!$BD$22,B10=角色卡!$BH$22,B10=角色卡!$BD$24,B10=角色卡!$BH$24),"",ROW()) -> 10 | I10: {=IFERROR(INDEX(灵能印记!$B:$B,SMALL(灵能印记!$E:$E,ROWS(灵能印记!$A$4:$A10))),"")} -> 失衡 | J10: {=IFERROR(INDEX(灵能印记!$B:$B,SMALL(灵能印记!$F:$F,ROWS(灵能印记!$A$4:$A10))),"")} -> 失衡 | K10: {=IFERROR(INDEX(灵能印记!$B:$B,SMALL(灵能印记!$G:$G,ROWS(灵能印记!$A$4:$A10))),"")} -> 失衡 | L10: {=IFERROR(INDEX(灵能印记!$B:$B,SMALL(灵能印记!$H:$H,ROWS(灵能印记!$A$4:$A10))),"")} -> 失衡
B11: 守护 | C11: 武器适合用于抵挡攻击或是规避伤害 | E11: =IF(OR(B11=角色卡!$BD$22,B11=角色卡!$BH$22,B11=角色卡!$BD$24,B11=角色卡!$BH$24),"",ROW()) -> 11 | F11: =IF(OR(B11=角色卡!$BD$22,B11=角色卡!$BH$22,B11=角色卡!$BD$24,B11=角色卡!$BH$24),"",ROW()) -> 11 | G11: =IF(OR(B11=角色卡!$BD$22,B11=角色卡!$BH$22,B11=角色卡!$BD$24,B11=角色卡!$BH$24),"",ROW()) -> 11 | H11: =IF(OR(B11=角色卡!$BD$22,B11=角色卡!$BH$22,B11=角色卡!$BD$24,B11=角色卡!$BH$24),"",ROW()) -> 11 | I11: {=IFERROR(INDEX(灵能印记!$B:$B,SMALL(灵能印记!$E:$E,ROWS(灵能印记!$A$4:$A11))),"")} -> 守护 | J11: {=IFERROR(INDEX(灵能印记!$B:$B,SMALL(灵能印记!$F:$F,ROWS(灵能印记!$A$4:$A11))),"")} -> 守护 | K11: {=IFERROR(INDEX(灵能印记!$B:$B,SMALL(灵能印记!$G:$G,ROWS(灵能印记!$A$4:$A11))),"")} -> 守护 | L11: {=IFERROR(INDEX(灵能印记!$B:$B,SMALL(灵能印记!$H:$H,ROWS(灵能印记!$A$4:$A11))),"")} -> 守护
B12: 多重 | C12: 你持有武器是复数的，通常是一组造型相似的武器。它们为你在战斗时带来了数量上的优势 | E12: =IF(OR(B12=角色卡!$BD$22,B12=角色卡!$BH$22,B12=角色卡!$BD$24,B12=角色卡!$BH$24),"",ROW()) -> 12 | F12: =IF(OR(B12=角色卡!$BD$22,B12=角色卡!$BH$22,B12=角色卡!$BD$24,B12=角色卡!$BH$24),"",ROW()) -> 12 | G12: =IF(OR(B12=角色卡!$BD$22,B12=角色卡!$BH$22,B12=角色卡!$BD$24,B12=角色卡!$BH$24),"",ROW()) -> 12 | H12: =IF(OR(B12=角色卡!$BD$22,B12=角色卡!$BH$22,B12=角色卡!$BD$24,B12=角色卡!$BH$24),"",ROW()) -> 12 | I12: {=IFERROR(INDEX(灵能印记!$B:$B,SMALL(灵能印记!$E:$E,ROWS(灵能印记!$A$4:$A12))),"")} -> 多重 | J12: {=IFERROR(INDEX(灵能印记!$B:$B,SMALL(灵能印记!$F:$F,ROWS(灵能印记!$A$4:$A12))),"")} -> 多重 | K12: {=IFERROR(INDEX(灵能印记!$B:$B,SMALL(灵能印记!$G:$G,ROWS(灵能印记!$A$4:$A12))),"")} -> 多重 | L12: {=IFERROR(INDEX(灵能印记!$B:$B,SMALL(灵能印记!$H:$H,ROWS(灵能印记!$A$4:$A12))),"")} -> 多重
B13: 组合 | C13: 武器由数个你自行决定的部件组合而成，这使得武器可以分开，也可以组合成型，即使其外观看起来无法做到 | E13: =IF(OR(B13=角色卡!$BD$22,B13=角色卡!$BH$22,B13=角色卡!$BD$24,B13=角色卡!$BH$24),"",ROW()) -> 13 | F13: =IF(OR(B13=角色卡!$BD$22,B13=角色卡!$BH$22,B13=角色卡!$BD$24,B13=角色卡!$BH$24),"",ROW()) -> 13 | G13: =IF(OR(B13=角色卡!$BD$22,B13=角色卡!$BH$22,B13=角色卡!$BD$24,B13=角色卡!$BH$24),"",ROW()) -> 13 | H13: =IF(OR(B13=角色卡!$BD$22,B13=角色卡!$BH$22,B13=角色卡!$BD$24,B13=角色卡!$BH$24),"",ROW()) -> 13 | I13: {=IFERROR(INDEX(灵能印记!$B:$B,SMALL(灵能印记!$E:$E,ROWS(灵能印记!$A$4:$A13))),"")} -> 组合 | J13: {=IFERROR(INDEX(灵能印记!$B:$B,SMALL(灵能印记!$F:$F,ROWS(灵能印记!$A$4:$A13))),"")} -> 组合 | K13: {=IFERROR(INDEX(灵能印记!$B:$B,SMALL(灵能印记!$G:$G,ROWS(灵能印记!$A$4:$A13))),"")} -> 组合 | L13: {=IFERROR(INDEX(灵能印记!$B:$B,SMALL(灵能印记!$H:$H,ROWS(灵能印记!$A$4:$A13))),"")} -> 组合
B14: 分身 | C14: 武器可以分裂或衍生出其复制体 | E14: =IF(OR(B14=角色卡!$BD$22,B14=角色卡!$BH$22,B14=角色卡!$BD$24,B14=角色卡!$BH$24),"",ROW()) -> 14 | F14: =IF(OR(B14=角色卡!$BD$22,B14=角色卡!$BH$22,B14=角色卡!$BD$24,B14=角色卡!$BH$24),"",ROW()) -> 14 | G14: =IF(OR(B14=角色卡!$BD$22,B14=角色卡!$BH$22,B14=角色卡!$BD$24,B14=角色卡!$BH$24),"",ROW()) -> 14 | H14: =IF(OR(B14=角色卡!$BD$22,B14=角色卡!$BH$22,B14=角色卡!$BD$24,B14=角色卡!$BH$24),"",ROW()) -> 14 | I14: {=IFERROR(INDEX(灵能印记!$B:$B,SMALL(灵能印记!$E:$E,ROWS(灵能印记!$A$4:$A14))),"")} -> 分身 | J14: {=IFERROR(INDEX(灵能印记!$B:$B,SMALL(灵能印记!$F:$F,ROWS(灵能印记!$A$4:$A14))),"")} -> 分身 | K14: {=IFERROR(INDEX(灵能印记!$B:$B,SMALL(灵能印记!$G:$G,ROWS(灵能印记!$A$4:$A14))),"")} -> 分身 | L14: {=IFERROR(INDEX(灵能印记!$B:$B,SMALL(灵能印记!$H:$H,ROWS(灵能印记!$A$4:$A14))),"")} -> 分身
B15: 悬空 | C15: 武器可以随你意志漂浮在空中 | E15: =IF(OR(B15=角色卡!$BD$22,B15=角色卡!$BH$22,B15=角色卡!$BD$24,B15=角色卡!$BH$24),"",ROW()) -> 15 | F15: =IF(OR(B15=角色卡!$BD$22,B15=角色卡!$BH$22,B15=角色卡!$BD$24,B15=角色卡!$BH$24),"",ROW()) -> 15 | G15: =IF(OR(B15=角色卡!$BD$22,B15=角色卡!$BH$22,B15=角色卡!$BD$24,B15=角色卡!$BH$24),"",ROW()) -> 15 | H15: =IF(OR(B15=角色卡!$BD$22,B15=角色卡!$BH$22,B15=角色卡!$BD$24,B15=角色卡!$BH$24),"",ROW()) -> 15 | I15: {=IFERROR(INDEX(灵能印记!$B:$B,SMALL(灵能印记!$E:$E,ROWS(灵能印记!$A$4:$A15))),"")} -> 悬空 | J15: {=IFERROR(INDEX(灵能印记!$B:$B,SMALL(灵能印记!$F:$F,ROWS(灵能印记!$A$4:$A15))),"")} -> 悬空 | K15: {=IFERROR(INDEX(灵能印记!$B:$B,SMALL(灵能印记!$G:$G,ROWS(灵能印记!$A$4:$A15))),"")} -> 悬空 | L15: {=IFERROR(INDEX(灵能印记!$B:$B,SMALL(灵能印记!$H:$H,ROWS(灵能印记!$A$4:$A15))),"")} -> 悬空
... B29: 幻映 | C29: 武器表面可投射预设光影图像 | E29: =IF(OR(B29=角色卡!$BD$22,B29=角色卡!$BH$22,B29=角色卡!$BD$24,B29=角色卡!$BH$24),"",ROW()) -> 29 | F29: =IF(OR(B29=角色卡!$BD$22,B29=角色卡!$BH$22,B29=角色卡!$BD$24,B29=角色卡!$BH$24),"",ROW()) -> 29 | G29: =IF(OR(B29=角色卡!$BD$22,B29=角色卡!$BH$22,B29=角色卡!$BD$24,B29=角色卡!$BH$24),"",ROW()) -> 29 | H29: =IF(OR(B29=角色卡!$BD$22,B29=角色卡!$BH$22,B29=角色卡!$BD$24,B29=角色卡!$BH$24),"",ROW()) -> 29 | I29: {=IFERROR(INDEX(灵能印记!$B:$B,SMALL(灵能印记!$E:$E,ROWS(灵能印记!$A$4:$A29))),"")} -> 幻映 | J29: {=IFERROR(INDEX(灵能印记!$B:$B,SMALL(灵能印记!$F:$F,ROWS(灵能印记!$A$4:$A29))),"")} -> 幻映 | K29: {=IFERROR(INDEX(灵能印记!$B:$B,SMALL(灵能印记!$G:$G,ROWS(灵能印记!$A$4:$A29))),"")} -> 幻映 | L29: {=IFERROR(INDEX(灵能印记!$B:$B,SMALL(灵能印记!$H:$H,ROWS(灵能印记!$A$4:$A29))),"")} -> 幻映
E30: =IF(OR(B30=角色卡!$BD$22,B30=角色卡!$BH$22,B30=角色卡!$BD$24,B30=角色卡!$BH$24),"",ROW()) -> 30 | F30: =IF(OR(B30=角色卡!$BD$22,B30=角色卡!$BH$22,B30=角色卡!$BD$24,B30=角色卡!$BH$24),"",ROW()) -> 30 | G30: =IF(OR(B30=角色卡!$BD$22,B30=角色卡!$BH$22,B30=角色卡!$BD$24,B30=角色卡!$BH$24),"",ROW()) -> 30 | H30: =IF(OR(B30=角色卡!$BD$22,B30=角色卡!$BH$22,B30=角色卡!$BD$24,B30=角色卡!$BH$24),"",ROW()) -> 30 | I30: {=IFERROR(INDEX(灵能印记!$B:$B,SMALL(灵能印记!$E:$E,ROWS(灵能印记!$A$4:$A30))),"")} | J30: {=IFERROR(INDEX(灵能印记!$B:$B,SMALL(灵能印记!$F:$F,ROWS(灵能印记!$A$4:$A30))),"")} | K30: {=IFERROR(INDEX(灵能印记!$B:$B,SMALL(灵能印记!$G:$G,ROWS(灵能印记!$A$4:$A30))),"")} | L30: {=IFERROR(INDEX(灵能印记!$B:$B,SMALL(灵能印记!$H:$H,ROWS(灵能印记!$A$4:$A30))),"")}

Sheet 专长
B2: 专长表 | E2: =IF(TRIM(角色卡!E35)="","",IFERROR(VLOOKUP(角色卡!E35,专长!$B$4:$C$32,2,0),"")) | F2: =IF(TRIM(角色卡!AU35)="","",IFERROR(VLOOKUP(角色卡!AU35,专长!$B$4:$C$32,2,0),""))
B3: 名称 | C3: 描述
B4: 深度灵体合一 | C4: 你的生命值上限恒定变为 1 点，然后把减少的自己的生命值上限按照 1 : 4 的比例转化为灵力值上限（即 1 点生命值上限= 4 点灵力值上限），但是你的灵力值上限 -5 点。 你的生命值上限获得 1 点提升时，也会变为提升 4 点灵力值上限。 当你受到【伤害】时，你可以选择消耗 4 点灵力值令该【伤害】减少1级。 | G4: =IF(OR(B4=角色卡!$E$35,B4=角色卡!$AU$35),"",ROW()) -> 4 | H4: =IF(OR(B4=角色卡!$E$35,B4=角色卡!$AU$35),"",ROW()) -> 4 | I4: {=IFERROR(INDEX(专长!$B:$B,SMALL(专长!$G:$G,ROWS(专长!$A$4:$A4))),"")} -> 深度灵体合一 | J4: {=IFERROR(INDEX(专长!$B:$B,SMALL(H:H,ROWS(专长!$A$4:$A4))),"")} -> 深度灵体合一
B5: 人生如戏 | C5: 当你获得 1 枚时髦骰时，你会立即获得 1d4 点时髦值。 | G5: =IF(OR(B5=角色卡!$E$35,B5=角色卡!$AU$35),"",ROW()) -> 5 | H5: =IF(OR(B5=角色卡!$E$35,B5=角色卡!$AU$35),"",ROW()) -> 5 | I5: {=IFERROR(INDEX(专长!$B:$B,SMALL(专长!$G:$G,ROWS(专长!$A$4:$A5))),"")} -> 人生如戏 | J5: {=IFERROR(INDEX(专长!$B:$B,SMALL(H:H,ROWS(专长!$A$4:$A5))),"")} -> 人生如戏
B6: 同仇 | C6: 如果你和具有同仇专长的生物在一个行动顺序中，你们进行攻击检定时会获得 1 枚加骰。 | G6: =IF(OR(B6=角色卡!$E$35,B6=角色卡!$AU$35),"",ROW()) -> 6 | H6: =IF(OR(B6=角色卡!$E$35,B6=角色卡!$AU$35),"",ROW()) -> 6 | I6: {=IFERROR(INDEX(专长!$B:$B,SMALL(专长!$G:$G,ROWS(专长!$A$4:$A6))),"")} -> 同仇 | J6: {=IFERROR(INDEX(专长!$B:$B,SMALL(H:H,ROWS(专长!$A$4:$A6))),"")} -> 同仇
B7: 灵力觉醒 | C7: 若在一次行动检定中，你通过激活灵能力标签获得加骰，你可以将其中一枚 D4 取满。 | G7: =IF(OR(B7=角色卡!$E$35,B7=角色卡!$AU$35),"",ROW()) -> 7 | H7: =IF(OR(B7=角色卡!$E$35,B7=角色卡!$AU$35),"",ROW()) -> 7 | I7: {=IFERROR(INDEX(专长!$B:$B,SMALL(专长!$G:$G,ROWS(专长!$A$4:$A7))),"")} -> 灵力觉醒 | J7: {=IFERROR(INDEX(专长!$B:$B,SMALL(H:H,ROWS(专长!$A$4:$A7))),"")} -> 灵力觉醒
B8: 星聚体 | C8: 你在从当前场景进入到下一个场景时，会恢复 5 点灵力值。 | G8: =IF(OR(B8=角色卡!$E$35,B8=角色卡!$AU$35),"",ROW()) -> 8 | H8: =IF(OR(B8=角色卡!$E$35,B8=角色卡!$AU$35),"",ROW()) -> 8 | I8: {=IFERROR(INDEX(专长!$B:$B,SMALL(专长!$G:$G,ROWS(专长!$A$4:$A8))),"")} -> 星聚体 | J8: {=IFERROR(INDEX(专长!$B:$B,SMALL(H:H,ROWS(专长!$A$4:$A8))),"")} -> 星聚体
B9: 武神体 | C9: 施展武技进行攻击检定时，你可以通过减少通过武技强度获得的加骰来减少该武技的灵力值消耗，每减少 1 枚加骰，武技的灵力值消耗也减少 1 点。 但无论如何，武技的灵力值消耗不能低于 1 点。 | G9: =IF(OR(B9=角色卡!$E$35,B9=角色卡!$AU$35),"",ROW()) -> 9 | H9: =IF(OR(B9=角色卡!$E$35,B9=角色卡!$AU$35),"",ROW()) -> 9 | I9: {=IFERROR(INDEX(专长!$B:$B,SMALL(专长!$G:$G,ROWS(专长!$A$4:$A9))),"")} -> 武神体 | J9: {=IFERROR(INDEX(专长!$B:$B,SMALL(H:H,ROWS(专长!$A$4:$A9))),"")} -> 武神体
B10: 逆势而上 | C10: 选择反击进行的攻击检定承受的减值减少 5 点。 | G10: =IF(OR(B10=角色卡!$E$35,B10=角色卡!$AU$35),"",ROW()) -> 10 | H10: =IF(OR(B10=角色卡!$E$35,B10=角色卡!$AU$35),"",ROW()) -> 10 | I10: {=IFERROR(INDEX(专长!$B:$B,SMALL(专长!$G:$G,ROWS(专长!$A$4:$A10))),"")} -> 逆势而上 | J10: {=IFERROR(INDEX(专长!$B:$B,SMALL(H:H,ROWS(专长!$A$4:$A10))),"")} -> 逆势而上
B11: 人名树影 | C11: 每场游戏聚会开始时，如果时髦值低于 20 点，你的时髦值会变为 20 点。 | G11: =IF(OR(B11=角色卡!$E$35,B11=角色卡!$AU$35),"",ROW()) -> 11 | H11: =IF(OR(B11=角色卡!$E$35,B11=角色卡!$AU$35),"",ROW()) -> 11 | I11: {=IFERROR(INDEX(专长!$B:$B,SMALL(专长!$G:$G,ROWS(专长!$A$4:$A11))),"")} -> 人名树影 | J11: {=IFERROR(INDEX(专长!$B:$B,SMALL(H:H,ROWS(专长!$A$4:$A11))),"")} -> 人名树影
B12: 先先之先 | C12: 若目标对你进行的攻击检定，你可在得出总值后再选择是防御还是反击。（注：具有先先之先的角色被武技：轮华攻击时，施展轮华的角色无论如何都不会获得加骰） | G12: =IF(OR(B12=角色卡!$E$35,B12=角色卡!$AU$35),"",ROW()) -> 12 | H12: =IF(OR(B12=角色卡!$E$35,B12=角色卡!$AU$35),"",ROW()) -> 12 | I12: {=IFERROR(INDEX(专长!$B:$B,SMALL(专长!$G:$G,ROWS(专长!$A$4:$A12))),"")} -> 先先之先 | J12: {=IFERROR(INDEX(专长!$B:$B,SMALL(H:H,ROWS(专长!$A$4:$A12))),"")} -> 先先之先
B13: 战斗医师 | C13: 当你在战斗中对目标造成【恢复】时，额外恢复目标 1 点生命值。 | G13: =IF(OR(B13=角色卡!$E$35,B13=角色卡!$AU$35),"",ROW()) -> 13 | H13: =IF(OR(B13=角色卡!$E$35,B13=角色卡!$AU$35),"",ROW()) -> 13 | I13: {=IFERROR(INDEX(专长!$B:$B,SMALL(专长!$G:$G,ROWS(专长!$A$4:$A13))),"")} -> 战斗医师 | J13: {=IFERROR(INDEX(专长!$B:$B,SMALL(H:H,ROWS(专长!$A$4:$A13))),"")} -> 战斗医师
B14: 灵能导师 | C14: 你施展术法消耗的灵力值始终减少 1 点，但减少后的术法灵力值消耗不能低于 1 点。 | G14: =IF(OR(B14=角色卡!$E$35,B14=角色卡!$AU$35),"",ROW()) -> 14 | H14: =IF(OR(B14=角色卡!$E$35,B14=角色卡!$AU$35),"",ROW()) -> 14 | I14: {=IFERROR(INDEX(专长!$B:$B,SMALL(专长!$G:$G,ROWS(专长!$A$4:$A14))),"")} -> 灵能导师 | J14: {=IFERROR(INDEX(专长!$B:$B,SMALL(H:H,ROWS(专长!$A$4:$A14))),"")} -> 灵能导师
B15: 凶猛武士 | C15: 你施展武技造成的【伤害】会增加 1 级，但是其他【效果】都会减少 2 级。 | G15: =IF(OR(B15=角色卡!$E$35,B15=角色卡!$AU$35),"",ROW()) -> 15 | H15: =IF(OR(B15=角色卡!$E$35,B15=角色卡!$AU$35),"",ROW()) -> 15 | I15: {=IFERROR(INDEX(专长!$B:$B,SMALL(专长!$G:$G,ROWS(专长!$A$4:$A15))),"")} -> 凶猛武士 | J15: {=IFERROR(INDEX(专长!$B:$B,SMALL(H:H,ROWS(专长!$A$4:$A15))),"")} -> 凶猛武士
... B32: 灵兽招来 | C32: 你获得一只跟随着你的灵兽。规则上，他被视为两个灵兽【标签】，一个决定它的形态，一个决定它的异能。 【灵兽标签】激活规则：你激活该标签后，在一次聚会中你无法再激活该灵兽标签。 创建形态：灵兽的形态仅代表该灵兽的外在样貌，其造型来源于中外典籍当中的生物形象，你可以使用任意典籍中的生物形象来决定你的灵兽样貌，然后将生物的名字作为一个【灵兽标签】。 选择异能：你可以从下表中选择一个异能，这代表着你的灵兽所掌握的异能，同时也是一个【灵兽标签】。 【魅惑幻形】能够编织覆盖特定区域的环境，修改其中的光影与声音，引导目标的情绪产生波动。 【黄金守护】能够感知被埋藏的贵金属，将接触的金银转化为高速旋转的金属风暴。 【天象主宰】能够飞翔于天空当中，操控云层中的水汽凝结降雨，引导空气中的电荷生成雷电，改变局部气流方向。 【空间撕裂】能够干扰非实体屏障、阵法或结界，对空间结构造成不稳定裂缝。 【毒液审判】能够吐出加速伤口愈合的唾液与腐蚀伤口的毒液。 【净化圣域】能够通过触碰污染源，分解其中的毒素、诅咒能量或放射性物质。 【法典窃取】能够提取书籍、卷轴中的文字，将其转移到其余载体之上，并对文字的意思进行解读。 【地脉封镇】能够践踏地面使土壤岩层硬化，重组金属物品的分子排列以提升密度。 【雷鼓震魂】发出混合低频震动与高频雷音的咆哮，对实体物质产生共振，对灵体产生震荡波。 【瘴疠为膳】能够吸收附近的瘟疫毒气，从背部长出解毒的赤色菌菇。 【千影寻踪】可将自身影子分裂为九道，每道影子可独立追踪不同气味的来源。 【骨刃铸兵】可将骨头转化为青铜兵刃，兵刃形状可以根据自身意志变化。 【珠泪凝珀】可将眼泪通过接触水源生成琥珀，琥珀能够封存声音。 【织霞成锦】能够吞食晚霞吐出七彩锦缎，触碰锦缎者可减轻自身受到重力的影响。 【泉眼通幽】能够操控水脉制造漩涡通道，快速转移到水脉所流通的其他地点。 | G32: =IF(OR(B32=角色卡!$E$35,B32=角色卡!$AU$35),"",ROW()) -> 32 | H32: =IF(OR(B32=角色卡!$E$35,B32=角色卡!$AU$35),"",ROW()) -> 32 | I32: {=IFERROR(INDEX(专长!$B:$B,SMALL(专长!$G:$G,ROWS(专长!$A$4:$A32))),"")} -> 灵兽招来 | J32: {=IFERROR(INDEX(专长!$B:$B,SMALL(H:H,ROWS(专长!$A$4:$A32))),"")} -> 灵兽招来
G33: =IF(OR(B33=角色卡!$E$35,B33=角色卡!$AU$35),"",ROW()) -> 33 | H33: =IF(OR(B33=角色卡!$E$35,B33=角色卡!$AU$35),"",ROW()) -> 33 | I33: {=IFERROR(INDEX(专长!$B:$B,SMALL(专长!$G:$G,ROWS(专长!$A$4:$A33))),"")} | J33: {=IFERROR(INDEX(专长!$B:$B,SMALL(H:H,ROWS(专长!$A$4:$A33))),"")}

Sheet 绝技
B2: 绝技表
B3: 绝技类型 | C3: 对应魂魄 | D3: 司掌职能 | E3: 描述 | F3: 效果 | G3: 挡位
B4: 狞猎哨兵 | C4: 尸狗魄 | D4: 警觉 | E4: 尸狗魄，掌管你的警觉能力。使你时刻能够保持着对外界的警惕，感知周围环境的变化。一旦危险将至，你的心身都能够在瞬间警觉，化解或规避即将到来的危机。 当你施展此绝技时，你的尸狗魄将会与你选择解放的标签融为一体，并根据你的想象，召唤出你那如影随形的“哨兵”。 你可以自由决定这位“哨兵”的种类、外观又或是智能性。无论是传说中的伊芙利特，坚硬的钢铁巨像，还是忠诚的灵体猎犬都可以…当然，甚至可以是你自己。你只需要依据你的灵能力作出你认为最适合的描述即可。 任何对你不利的行为，统统都会被这位“哨兵”妨碍、阻挡、干扰或击落，使你能够更有效地应对敌人。 | F4: 任何对你根据【成功等级】造成的【效果】会视为减少2*X个【成功等级】（X=你解放的标签数量），持续到你离开当前场景。 | G4: 一 挡 | I4: =IF(角色卡!$BN$22=0,"",VLOOKUP(角色卡!$BN$22,绝技!$B$4:$F$11,5,0))
B5: 闪灵罗网 | C5: 伏矢魄 | D5: 思维与反应力 | E5: 伏矢魄，掌管你的思维意识。它反映着你对一个事物的认知、思考和判断能力，同时还控制着你在面对各类突发情况时的反应速度。 当你施展此绝技时，你的伏矢魄与你选择解放的标签，将会根据你的想象交缠融合，并强化你的反射神经和反应速度，使你能够在短时间内获得超人的机动力。 你可以自由描述你的灵能力是如何帮助你获得提升。这可以是一种针对肉体筋骨的辅助工具，也可以是对意识精神的自我强化。你只需要依据你的灵能力作出你认为最适合的描述即可。 机动力获得提升的你，能够在瞬间预测各种动作并从中选择出最优的解决方案。如同你独自编织出一张充满可能性的捕网，无论猎物逃往何方，你都能将其收入其中。 | F5: 你的武技强度，术法强度和灵能力强度增加X点（X=你解放的标签数量/2（向下取整））。
B6: 铄命药釜 | C6: 雀阴魄 | D6: 生命力与恢复力 | E6: 雀阴魄，司掌你的生命力与恢复力。你的生命活力和你的自我治愈能力皆源于此；同时它还象征着人类的繁衍和生命的延续。 当你施展此绝技时，根据你的想象，你选择解放的标签会被创造成一个神圣的密封炊具，你的雀阴魄则会成为其中的神圣煮物。 你可以自由决定炊具的造型、形状、大小和装饰；以及炊具最终呈现的煮物是什么。从真正煎制沸腾药物的药罐，到西方宗教下的瓶装圣水，又或是熬煮的家常粥水都没有问题。你只需要依据你的灵能力作出你认为最适合的描述即可。 当煮物完成烹制后，炊具会发出一声提示。服食或被浇洒神圣煮物的生物将会获得你所指定的增益。 | F6: 当你进行攻击检定对场景中的生物造成【伤害】后，你可以指定另一个生物（包括你自己），然后选择以下其一，直到你离开该场景： ·造成【恢复X】（X=你解放标签的数量）； ·造成【恢复灵力X】（X=你解放标签的数量）。
B7: 狂魄武装 | C7: 吞贼魄 | D7: 外在抗御能力 | E7: 吞贼魄，象征你抵抗外敌的防御能力。它如同你身体内的免疫系统，是你坚实的防护盾，保护你免受伤痛疾病的侵扰。 当你施展此绝技时，你的吞贼魄与你选择解放的标签将会覆盖你的身体，并根据你的想象，转化为你的外在装甲。 你可以综合考虑你的灵能力，来决定这套装甲的造型、材质、色彩等装饰细节。它可以是神话中的伟大铠甲，可以是轻披在身的霓裳羽衣，甚至也可以是一种不具备物理形态的抽象概念。你只需要依据你的灵能力作出你认为最适合的描述即可。 身披盔甲的你能够在自己或是其他生物防御时提供强而有力的支持，即使是抗击最强大的敌人也毫不畏惧。 | F7: ·当场景内有生物选择反击时，你可以让其进行的攻击检定获得5点加值。 ·当场景内有生物选择防御时，你可以让那次攻击检定的挑战值增加5点。 你可以使用该能力X次，直到你离开该场景。（X=你解放标签的数量两倍）
B8: 辟害符佩 | C8: 非毒魄 | D8: 内在化解能力 | E8: 非毒魄，掌管你排除要害的能力。使得你可以仅凭自身便将体内积聚的“毒素”化解。所谓“毒素”，不仅是指由外界侵入体内的有害物质，还包括你的情绪所带来的不良影响。 当你施展此绝技时，你的非毒魄与你选择解放的标签将被结合雕琢，并根据你的想象，变化为一件有形的灵符配饰。 你可以自由决定配饰的形状、造型以及配饰上刻画的灵符纹样。这可以是一件端庄的玉佩、一条典雅的项链、一枚权威的玺戒又或是一顶威严的皇冠。你只需要依据你的灵能力作出你认为最适合的描述即可。 刻有灵幻符咒的配饰能够保护你或你的盟友，帮助你们化解那些尝试侵入你们的负面因素，使你们时刻保持肉体与精神的平衡。 | F8: 你可以对场景中你选择的目标造成【清除效果X】（X*3为你解放标签的数量）
B9: 净灵环 | C9: 除秽魄 | D9: 净化能力 | E9: 除秽魄，掌控你的自我净化能力。它不仅会帮助你清除身体代谢而产生的废物，同时还控制着你抵抗邪魔外道干扰、入侵的能力。 当你施展此绝技时，你的除秽魄将会与你选择解放的标签转化为两个光点缠绕在你身边。再根据你的想象，在空中快速划动，并形成两个盘旋的圆环。 你可以自由决定圆环的大小、材质、造型以及其他装饰细节。从细小的两枚指环，到扣于双臂的手镯，抑或踏于双脚之下的火轮都可以。你只需要依据你的灵能力作出你认为最适合的描述即可。 圆环成对，此阴彼阳，散发着神圣洁净的微光。它遵循着你的指令，为你或是你的盟友驱赶黑暗、邪祟之气。 | F9: 当场景内有生物类型为鬼魂的敌人进行攻击检定时，总值必须减去额外投掷X枚D4骰的结果，效果持续到你离开该场景。（X为你解放标签的数量）
B10: 灵气自在功法 | C10: 臭肺魄 | D10: 气息控制能力 | E10: 臭肺魄，管理着你的呼吸功能。它负责调节你因身体状态变化而产生的氧气的供给需求。确保你能够时刻保持呼吸平稳顺畅，以进一步提升你的内在修为。 你施展此绝技时，臭肺魄将会与你选择解放的标签合而为一，并重新回到你的体内。然后根据你的想象，成为一套由你自行领悟的特殊招式。 如何演绎这套招式由你自行决定。它们可以是对真实存在的武术的戏仿或致敬，也可以是一套由你完全原创的武学招数。你可以优先依据你的灵能力作出你认为最适合的描述。 通过应用灵气自在功法，可以让你做到心神合一。在短时间内，极大幅度地提升你的灵能力，并强化你对灵能力的应用。 | F10: 你可以让你进行行动检定获得的加骰从D4变为D6。 你可以使用该能力X次，效果持续到你离开该场景。（X为你解放标签的数量）
B12: 降神嗔令 | C12: 胎光魂 | D12: 生息与死灭 | E12: 胎光魂，是你的生命灯火，决定着你的生死存亡。一旦这生命火光熄灭，那就代表死期将至。此火乃至纯至阳，可将你的意识与诸天神相联，使你在短时间内成为半人半神的存在，助你降魔伏妖。 当你施展此绝技时，你选择解放的标签，将会缠绕你的胎光魂，并根据你的想象，化作一道代表神的令牌。 你可以自行决定令牌的样式、造型，大小以及刻画在上面的符咒和敕令。无论是传统道教仪式中的令牌，还是古代军队中用于发号司令的虎符，又或是一部戏谑的现代智能手机，都可以是对令牌的描述。你只需要依据你的灵能力作出你认为适合的描述即可。 手持令牌，你将获得接近于神的威能，可用于保卫你的盟友，以及击溃你的敌人。 | F12: 你指定X个目标，你与你选择的目标获得【物理免疫】，以及一个你指定类型的【伤害抗性X】。（X为你解放标签的数量） 此外，你与你选择的目标造成【伤害】时，全部变为【湮灭伤害】。 | G12: 二 挡 | I12: =IF(角色卡!$BZ$22=0,"",VLOOKUP(角色卡!$BZ$22,绝技!$B$12:$F$15,5,0))
B13: 钦法愚印 | C13: 爽灵魂 | D13: 智慧与感知 | E13: 爽灵魂，是你的智慧之源。它掌管你的智力、判断力及感知能力。也管理着你与诸天神沟通的灵性之力。 施展此绝技时，你选择解放的标签，并重构你的爽灵魂，根据你的想象重新组合成一尊法印。 你可以自行决定法印的造型、材质以及篆刻在上面的印鉴样式。从失落的传国玉玺，到形态各异的古铜印，又或是火漆印章，甚至是玩具印章或是潮流贴纸。你只需要依据灵能力作出适合的描述即可。 当你为你的盟友盖下法印，意味着你们已经可以借用天神之力。即使是对术法一无所知的莽夫，也能通过天神附体施展奇迹。 | F13: 你从普通或秘传凭术列表中选择一项，指定除你以外的X个目标，你与目标不需要习得这项凭术就可以施展它，同时不需要任何消耗。（X为你解放标签的数量）
B14: 振欲旗幡 | C14: 幽精魂 | D14: 心灵与情感 | E14: 幽精魂，主宰你的性情与情绪。它管理着你的欲望、梦境与潜意识，是你内心最深处不曾向人表露过的一面。 施展此绝技时，你将选择解放的标签，并与你的幽精魂交织相融，根据想象编织成一杆令旗。 你可以自行决定令旗的大小形状、材质用料，以及旗上的装饰刺绣或图纹样式。可以基于现实中存在的旗帜进行再创作；也可以动手绘画一面原创的旗帜；这面旗帜甚至不一定是传统意义上的“旗”，只需要依据你的灵能力作出你认为适合的描述即可。 每当你挥动旗幡，你都将会为你和你的盟友招来福佑，为你的敌人送去灾祸。 | F14: 你从《通用效果表》中选择一种【效果】，然后选择若干个目标，对目标造成具有X的成功等级的该【效果】。每个轮次开始时，你都可以对目标造成你选择【效果X】。（X为你解放标签的数量）

Sheet 更新日志
A1: 版本 | B1: 发布时间 | D1: 说明
A2: V1.0 | B2: 2025.11.28 | D2: 具备大多数功能，可以正常使用的基础版本。兼容《边缘人扮演指南》。 为便于滚轮翻阅过长条目，主表中部分格子（如武技效果）需手动下拉选择。更换后需手动重选。 在主表各处添加了“☑”，以便确认该模块是否可用。
A5: V1.1 | B5: 2025.11.29 | D5: 修bug。为生命值和灵力值添加了适配专长“深度灵体合一”的变动。
A6: V1.2 | B6: 2025.11.30 | D6: 修bug。同步狩魂者青果骰插件更新，添加“事件业力”至录卡数据。
A7: V1.3 | B7: 2025.12.17 | D7: 根据核心规则V1.0书签版修正部分内容，补充“无畏守护”时髦风格、侠界联动时髦风格。 取消了武技表与术法表“风味描述”的保护，以便有需求者手动修改。（注意，这会损坏原始描述！） 修bug。修正了录卡模块的指导描述。
A10: V1.4 | B10: 2026.1.25 | D10: 修正一挡绝技效果显示bug，修改主表版头显示效果。

Sheet 空白
